[2025-10-04 01:47:39.488] {                 Renderable.py: 113} (              UIMain3DSub:   ERROR) - Unable to create a Vertex Array because:
Traceback (most recent call last):
  File "/Users/dominiklang/Artemotion/venv/lib/python3.11/site-packages/OpenGL/latebind.py", line 43, in __call__
    return self._finalCall( *args, **named )
           ^^^^^^^^^^^^^^^^^^^^^^^^^^^^^^^^^
TypeError: 'NoneType' object is not callable

During handling of the above exception, another exception occurred:

Traceback (most recent call last):
  File "/Users/dominiklang/Artemotion/scripts/engine3d/core/GLVertexArray.py", line 32, in __init__
    self._va_id = pygl.glGenVertexArrays(1)
                  ^^^^^^^^^^^^^^^^^^^^^^^^^
  File "/Users/dominiklang/Artemotion/venv/lib/python3.11/site-packages/OpenGL/latebind.py", line 47, in __call__
    return self._finalCall( *args, **named )
           ^^^^^^^^^^^^^^^^^^^^^^^^^^^^^^^^^
  File "/Users/dominiklang/Artemotion/venv/lib/python3.11/site-packages/OpenGL/wrapper.py", line 771, in wrapperCall
    raise err
  File "/Users/dominiklang/Artemotion/venv/lib/python3.11/site-packages/OpenGL/wrapper.py", line 764, in wrapperCall
    result = wrappedOperation(*cArguments)
             ^^^^^^^^^^^^^^^^^^^^^^^^^^^^^
  File "/Users/dominiklang/Artemotion/venv/lib/python3.11/site-packages/OpenGL/platform/baseplatform.py", line 487, in __call__
    return self(*args, **named)
           ^^^^^^^^^^^^^^^^^^^^
  File "/Users/dominiklang/Artemotion/venv/lib/python3.11/site-packages/OpenGL/error.py", line 230, in glCheckError
    raise self._errorClass(
OpenGL.error.GLError: GLError(
	err = 1282,
	description = b'invalid operation',
	baseOperation = glGenVertexArrays,
	pyArgs = (1, <object object at 0x102210fd0>),
	cArgs = (1, array([0], dtype=uint32)),
	cArguments = (1, array([0], dtype=uint32))
)
[2025-10-04 01:47:39.509] {                       Room.py: 245} (              UIMain3DSub:   ERROR) - Unable to bind/set data to the aPos attribute because:
Traceback (most recent call last):
  File "/Users/dominiklang/Artemotion/scripts/engine3d/core/GLProgram.py", line 173, in set_attribute
    attr_loc = self.get_attribute_location(name=name)
               ^^^^^^^^^^^^^^^^^^^^^^^^^^^^^^^^^^^^^^
  File "/Users/dominiklang/Artemotion/scripts/engine3d/core/GLProgram.py", line 154, in get_attribute_location
    return pygl.glGetAttribLocation(self._id, name)
           ^^^^^^^^^^^^^^^^^^^^^^^^^^^^^^^^^^^^^^^^
  File "/Users/dominiklang/Artemotion/venv/lib/python3.11/site-packages/OpenGL/latebind.py", line 63, in __call__
    return self.wrapperFunction( self.baseFunction, *args, **named )
           ^^^^^^^^^^^^^^^^^^^^^^^^^^^^^^^^^^^^^^^^^^^^^^^^^^^^^^^^^
  File "/Users/dominiklang/Artemotion/venv/lib/python3.11/site-packages/OpenGL/GL/VERSION/GL_2_0.py", line 480, in glGetAttribLocation
    return baseOperation(program, name)
           ^^^^^^^^^^^^^^^^^^^^^^^^^^^^
  File "/Users/dominiklang/Artemotion/venv/lib/python3.11/site-packages/OpenGL/platform/baseplatform.py", line 487, in __call__
    return self(*args, **named)
           ^^^^^^^^^^^^^^^^^^^^
  File "/Users/dominiklang/Artemotion/venv/lib/python3.11/site-packages/OpenGL/error.py", line 230, in glCheckError
    raise self._errorClass(
OpenGL.error.GLError: GLError(
	err = 1282,
	description = b'invalid operation',
	baseOperation = glGetAttribLocation,
	cArguments = (6, b'aPos\x00'),
	result = -1
)
[2025-10-04 01:47:39.510] {                       Room.py: 282} (              UIMain3DSub:   ERROR) - Unable to use the GL program because:
Traceback (most recent call last):
  File "/Users/dominiklang/Artemotion/scripts/engine3d/core/GLProgram.py", line 131, in use
    pygl.glUseProgram(self._id)
  File "/Users/dominiklang/Artemotion/venv/lib/python3.11/site-packages/OpenGL/platform/baseplatform.py", line 487, in __call__
    return self(*args, **named)
           ^^^^^^^^^^^^^^^^^^^^
  File "/Users/dominiklang/Artemotion/venv/lib/python3.11/site-packages/OpenGL/error.py", line 230, in glCheckError
    raise self._errorClass(
OpenGL.error.GLError: GLError(
	err = 1282,
	description = b'invalid operation',
	baseOperation = glUseProgram,
	cArguments = (6,)
)
[2025-10-04 01:47:45.189] {                 Renderable.py: 183} (              UIMain3DSub:   ERROR) - Unable to use the GL program because:
Traceback (most recent call last):
  File "/Users/dominiklang/Artemotion/scripts/engine3d/core/GLProgram.py", line 131, in use
    pygl.glUseProgram(self._id)
  File "/Users/dominiklang/Artemotion/venv/lib/python3.11/site-packages/OpenGL/error.py", line 230, in glCheckError
    raise self._errorClass(
OpenGL.error.GLError: GLError(
	err = 1282,
	description = b'invalid operation',
	baseOperation = glUseProgram,
	cArguments = (6,)
)
[2025-10-04 01:47:45.206] {                 Renderable.py: 183} (              UIMain3DSub:   ERROR) - Unable to use the GL program because:
Traceback (most recent call last):
  File "/Users/dominiklang/Artemotion/scripts/engine3d/core/GLProgram.py", line 131, in use
    pygl.glUseProgram(self._id)
  File "/Users/dominiklang/Artemotion/venv/lib/python3.11/site-packages/OpenGL/error.py", line 230, in glCheckError
    raise self._errorClass(
OpenGL.error.GLError: GLError(
	err = 1282,
	description = b'invalid operation',
	baseOperation = glUseProgram,
	cArguments = (6,)
)
[2025-10-04 01:47:45.222] {                 Renderable.py: 183} (              UIMain3DSub:   ERROR) - Unable to use the GL program because:
Traceback (most recent call last):
  File "/Users/dominiklang/Artemotion/scripts/engine3d/core/GLProgram.py", line 131, in use
    pygl.glUseProgram(self._id)
  File "/Users/dominiklang/Artemotion/venv/lib/python3.11/site-packages/OpenGL/error.py", line 230, in glCheckError
    raise self._errorClass(
OpenGL.error.GLError: GLError(
	err = 1282,
	description = b'invalid operation',
	baseOperation = glUseProgram,
	cArguments = (6,)
)
[2025-10-04 01:47:45.239] {                 Renderable.py: 183} (              UIMain3DSub:   ERROR) - Unable to use the GL program because:
Traceback (most recent call last):
  File "/Users/dominiklang/Artemotion/scripts/engine3d/core/GLProgram.py", line 131, in use
    pygl.glUseProgram(self._id)
  File "/Users/dominiklang/Artemotion/venv/lib/python3.11/site-packages/OpenGL/error.py", line 230, in glCheckError
    raise self._errorClass(
OpenGL.error.GLError: GLError(
	err = 1282,
	description = b'invalid operation',
	baseOperation = glUseProgram,
	cArguments = (6,)
)
[2025-10-04 01:47:45.256] {                 Renderable.py: 183} (              UIMain3DSub:   ERROR) - Unable to use the GL program because:
Traceback (most recent call last):
  File "/Users/dominiklang/Artemotion/scripts/engine3d/core/GLProgram.py", line 131, in use
    pygl.glUseProgram(self._id)
  File "/Users/dominiklang/Artemotion/venv/lib/python3.11/site-packages/OpenGL/error.py", line 230, in glCheckError
    raise self._errorClass(
OpenGL.error.GLError: GLError(
	err = 1282,
	description = b'invalid operation',
	baseOperation = glUseProgram,
	cArguments = (6,)
)
[2025-10-04 01:47:45.272] {                 Renderable.py: 183} (              UIMain3DSub:   ERROR) - Unable to use the GL program because:
Traceback (most recent call last):
  File "/Users/dominiklang/Artemotion/scripts/engine3d/core/GLProgram.py", line 131, in use
    pygl.glUseProgram(self._id)
  File "/Users/dominiklang/Artemotion/venv/lib/python3.11/site-packages/OpenGL/error.py", line 230, in glCheckError
    raise self._errorClass(
OpenGL.error.GLError: GLError(
	err = 1282,
	description = b'invalid operation',
	baseOperation = glUseProgram,
	cArguments = (6,)
)
[2025-10-04 01:47:45.289] {                 Renderable.py: 183} (              UIMain3DSub:   ERROR) - Unable to use the GL program because:
Traceback (most recent call last):
  File "/Users/dominiklang/Artemotion/scripts/engine3d/core/GLProgram.py", line 131, in use
    pygl.glUseProgram(self._id)
  File "/Users/dominiklang/Artemotion/venv/lib/python3.11/site-packages/OpenGL/error.py", line 230, in glCheckError
    raise self._errorClass(
OpenGL.error.GLError: GLError(
	err = 1282,
	description = b'invalid operation',
	baseOperation = glUseProgram,
	cArguments = (6,)
)
[2025-10-04 01:47:45.296] {                 Renderable.py: 183} (              UIMain3DSub:   ERROR) - Unable to use the GL program because:
Traceback (most recent call last):
  File "/Users/dominiklang/Artemotion/scripts/engine3d/core/GLProgram.py", line 131, in use
    pygl.glUseProgram(self._id)
  File "/Users/dominiklang/Artemotion/venv/lib/python3.11/site-packages/OpenGL/error.py", line 230, in glCheckError
    raise self._errorClass(
OpenGL.error.GLError: GLError(
	err = 1282,
	description = b'invalid operation',
	baseOperation = glUseProgram,
	cArguments = (6,)
)
[2025-10-04 01:47:45.306] {                 Renderable.py: 183} (              UIMain3DSub:   ERROR) - Unable to use the GL program because:
Traceback (most recent call last):
  File "/Users/dominiklang/Artemotion/scripts/engine3d/core/GLProgram.py", line 131, in use
    pygl.glUseProgram(self._id)
  File "/Users/dominiklang/Artemotion/venv/lib/python3.11/site-packages/OpenGL/error.py", line 230, in glCheckError
    raise self._errorClass(
OpenGL.error.GLError: GLError(
	err = 1282,
	description = b'invalid operation',
	baseOperation = glUseProgram,
	cArguments = (6,)
)
[2025-10-04 01:47:45.334] {                 Renderable.py: 183} (              UIMain3DSub:   ERROR) - Unable to use the GL program because:
Traceback (most recent call last):
  File "/Users/dominiklang/Artemotion/scripts/engine3d/core/GLProgram.py", line 131, in use
    pygl.glUseProgram(self._id)
  File "/Users/dominiklang/Artemotion/venv/lib/python3.11/site-packages/OpenGL/error.py", line 230, in glCheckError
    raise self._errorClass(
OpenGL.error.GLError: GLError(
	err = 1282,
	description = b'invalid operation',
	baseOperation = glUseProgram,
	cArguments = (6,)
)
[2025-10-04 01:47:45.339] {                 Renderable.py: 183} (              UIMain3DSub:   ERROR) - Unable to use the GL program because:
Traceback (most recent call last):
  File "/Users/dominiklang/Artemotion/scripts/engine3d/core/GLProgram.py", line 131, in use
    pygl.glUseProgram(self._id)
  File "/Users/dominiklang/Artemotion/venv/lib/python3.11/site-packages/OpenGL/error.py", line 230, in glCheckError
    raise self._errorClass(
OpenGL.error.GLError: GLError(
	err = 1282,
	description = b'invalid operation',
	baseOperation = glUseProgram,
	cArguments = (6,)
)
[2025-10-04 01:47:45.363] {                 Renderable.py: 183} (              UIMain3DSub:   ERROR) - Unable to use the GL program because:
Traceback (most recent call last):
  File "/Users/dominiklang/Artemotion/scripts/engine3d/core/GLProgram.py", line 131, in use
    pygl.glUseProgram(self._id)
  File "/Users/dominiklang/Artemotion/venv/lib/python3.11/site-packages/OpenGL/error.py", line 230, in glCheckError
    raise self._errorClass(
OpenGL.error.GLError: GLError(
	err = 1282,
	description = b'invalid operation',
	baseOperation = glUseProgram,
	cArguments = (6,)
)
[2025-10-04 01:47:45.390] {                 Renderable.py: 183} (              UIMain3DSub:   ERROR) - Unable to use the GL program because:
Traceback (most recent call last):
  File "/Users/dominiklang/Artemotion/scripts/engine3d/core/GLProgram.py", line 131, in use
    pygl.glUseProgram(self._id)
  File "/Users/dominiklang/Artemotion/venv/lib/python3.11/site-packages/OpenGL/error.py", line 230, in glCheckError
    raise self._errorClass(
OpenGL.error.GLError: GLError(
	err = 1282,
	description = b'invalid operation',
	baseOperation = glUseProgram,
	cArguments = (6,)
)
[2025-10-04 01:47:45.400] {                 Renderable.py: 183} (              UIMain3DSub:   ERROR) - Unable to use the GL program because:
Traceback (most recent call last):
  File "/Users/dominiklang/Artemotion/scripts/engine3d/core/GLProgram.py", line 131, in use
    pygl.glUseProgram(self._id)
  File "/Users/dominiklang/Artemotion/venv/lib/python3.11/site-packages/OpenGL/error.py", line 230, in glCheckError
    raise self._errorClass(
OpenGL.error.GLError: GLError(
	err = 1282,
	description = b'invalid operation',
	baseOperation = glUseProgram,
	cArguments = (6,)
)
[2025-10-04 01:47:45.405] {                 Renderable.py: 183} (              UIMain3DSub:   ERROR) - Unable to use the GL program because:
Traceback (most recent call last):
  File "/Users/dominiklang/Artemotion/scripts/engine3d/core/GLProgram.py", line 131, in use
    pygl.glUseProgram(self._id)
  File "/Users/dominiklang/Artemotion/venv/lib/python3.11/site-packages/OpenGL/error.py", line 230, in glCheckError
    raise self._errorClass(
OpenGL.error.GLError: GLError(
	err = 1282,
	description = b'invalid operation',
	baseOperation = glUseProgram,
	cArguments = (6,)
)
[2025-10-04 01:47:45.422] {                 Renderable.py: 183} (              UIMain3DSub:   ERROR) - Unable to use the GL program because:
Traceback (most recent call last):
  File "/Users/dominiklang/Artemotion/scripts/engine3d/core/GLProgram.py", line 131, in use
    pygl.glUseProgram(self._id)
  File "/Users/dominiklang/Artemotion/venv/lib/python3.11/site-packages/OpenGL/error.py", line 230, in glCheckError
    raise self._errorClass(
OpenGL.error.GLError: GLError(
	err = 1282,
	description = b'invalid operation',
	baseOperation = glUseProgram,
	cArguments = (6,)
)
[2025-10-04 01:47:45.450] {                 Renderable.py: 183} (              UIMain3DSub:   ERROR) - Unable to use the GL program because:
Traceback (most recent call last):
  File "/Users/dominiklang/Artemotion/scripts/engine3d/core/GLProgram.py", line 131, in use
    pygl.glUseProgram(self._id)
  File "/Users/dominiklang/Artemotion/venv/lib/python3.11/site-packages/OpenGL/error.py", line 230, in glCheckError
    raise self._errorClass(
OpenGL.error.GLError: GLError(
	err = 1282,
	description = b'invalid operation',
	baseOperation = glUseProgram,
	cArguments = (6,)
)
[2025-10-04 01:47:45.472] {                 Renderable.py: 183} (              UIMain3DSub:   ERROR) - Unable to use the GL program because:
Traceback (most recent call last):
  File "/Users/dominiklang/Artemotion/scripts/engine3d/core/GLProgram.py", line 131, in use
    pygl.glUseProgram(self._id)
  File "/Users/dominiklang/Artemotion/venv/lib/python3.11/site-packages/OpenGL/error.py", line 230, in glCheckError
    raise self._errorClass(
OpenGL.error.GLError: GLError(
	err = 1282,
	description = b'invalid operation',
	baseOperation = glUseProgram,
	cArguments = (6,)
)
[2025-10-04 01:47:45.506] {                 Renderable.py: 183} (              UIMain3DSub:   ERROR) - Unable to use the GL program because:
Traceback (most recent call last):
  File "/Users/dominiklang/Artemotion/scripts/engine3d/core/GLProgram.py", line 131, in use
    pygl.glUseProgram(self._id)
  File "/Users/dominiklang/Artemotion/venv/lib/python3.11/site-packages/OpenGL/error.py", line 230, in glCheckError
    raise self._errorClass(
OpenGL.error.GLError: GLError(
	err = 1282,
	description = b'invalid operation',
	baseOperation = glUseProgram,
	cArguments = (6,)
)
[2025-10-04 01:47:45.539] {                 Renderable.py: 183} (              UIMain3DSub:   ERROR) - Unable to use the GL program because:
Traceback (most recent call last):
  File "/Users/dominiklang/Artemotion/scripts/engine3d/core/GLProgram.py", line 131, in use
    pygl.glUseProgram(self._id)
  File "/Users/dominiklang/Artemotion/venv/lib/python3.11/site-packages/OpenGL/error.py", line 230, in glCheckError
    raise self._errorClass(
OpenGL.error.GLError: GLError(
	err = 1282,
	description = b'invalid operation',
	baseOperation = glUseProgram,
	cArguments = (6,)
)
[2025-10-04 01:47:45.556] {                 Renderable.py: 183} (              UIMain3DSub:   ERROR) - Unable to use the GL program because:
Traceback (most recent call last):
  File "/Users/dominiklang/Artemotion/scripts/engine3d/core/GLProgram.py", line 131, in use
    pygl.glUseProgram(self._id)
  File "/Users/dominiklang/Artemotion/venv/lib/python3.11/site-packages/OpenGL/error.py", line 230, in glCheckError
    raise self._errorClass(
OpenGL.error.GLError: GLError(
	err = 1282,
	description = b'invalid operation',
	baseOperation = glUseProgram,
	cArguments = (6,)
)
[2025-10-04 01:47:45.572] {                 Renderable.py: 183} (              UIMain3DSub:   ERROR) - Unable to use the GL program because:
Traceback (most recent call last):
  File "/Users/dominiklang/Artemotion/scripts/engine3d/core/GLProgram.py", line 131, in use
    pygl.glUseProgram(self._id)
  File "/Users/dominiklang/Artemotion/venv/lib/python3.11/site-packages/OpenGL/error.py", line 230, in glCheckError
    raise self._errorClass(
OpenGL.error.GLError: GLError(
	err = 1282,
	description = b'invalid operation',
	baseOperation = glUseProgram,
	cArguments = (6,)
)
[2025-10-04 01:47:45.577] {                 Renderable.py: 183} (              UIMain3DSub:   ERROR) - Unable to use the GL program because:
Traceback (most recent call last):
  File "/Users/dominiklang/Artemotion/scripts/engine3d/core/GLProgram.py", line 131, in use
    pygl.glUseProgram(self._id)
  File "/Users/dominiklang/Artemotion/venv/lib/python3.11/site-packages/OpenGL/error.py", line 230, in glCheckError
    raise self._errorClass(
OpenGL.error.GLError: GLError(
	err = 1282,
	description = b'invalid operation',
	baseOperation = glUseProgram,
	cArguments = (6,)
)
[2025-10-04 01:47:45.589] {                 Renderable.py: 183} (              UIMain3DSub:   ERROR) - Unable to use the GL program because:
Traceback (most recent call last):
  File "/Users/dominiklang/Artemotion/scripts/engine3d/core/GLProgram.py", line 131, in use
    pygl.glUseProgram(self._id)
  File "/Users/dominiklang/Artemotion/venv/lib/python3.11/site-packages/OpenGL/error.py", line 230, in glCheckError
    raise self._errorClass(
OpenGL.error.GLError: GLError(
	err = 1282,
	description = b'invalid operation',
	baseOperation = glUseProgram,
	cArguments = (6,)
)
[2025-10-04 01:47:45.595] {                 Renderable.py: 183} (              UIMain3DSub:   ERROR) - Unable to use the GL program because:
Traceback (most recent call last):
  File "/Users/dominiklang/Artemotion/scripts/engine3d/core/GLProgram.py", line 131, in use
    pygl.glUseProgram(self._id)
  File "/Users/dominiklang/Artemotion/venv/lib/python3.11/site-packages/OpenGL/error.py", line 230, in glCheckError
    raise self._errorClass(
OpenGL.error.GLError: GLError(
	err = 1282,
	description = b'invalid operation',
	baseOperation = glUseProgram,
	cArguments = (6,)
)
[2025-10-04 01:47:45.605] {                 Renderable.py: 183} (              UIMain3DSub:   ERROR) - Unable to use the GL program because:
Traceback (most recent call last):
  File "/Users/dominiklang/Artemotion/scripts/engine3d/core/GLProgram.py", line 131, in use
    pygl.glUseProgram(self._id)
  File "/Users/dominiklang/Artemotion/venv/lib/python3.11/site-packages/OpenGL/error.py", line 230, in glCheckError
    raise self._errorClass(
OpenGL.error.GLError: GLError(
	err = 1282,
	description = b'invalid operation',
	baseOperation = glUseProgram,
	cArguments = (6,)
)
[2025-10-04 01:47:45.610] {                 Renderable.py: 183} (              UIMain3DSub:   ERROR) - Unable to use the GL program because:
Traceback (most recent call last):
  File "/Users/dominiklang/Artemotion/scripts/engine3d/core/GLProgram.py", line 131, in use
    pygl.glUseProgram(self._id)
  File "/Users/dominiklang/Artemotion/venv/lib/python3.11/site-packages/OpenGL/error.py", line 230, in glCheckError
    raise self._errorClass(
OpenGL.error.GLError: GLError(
	err = 1282,
	description = b'invalid operation',
	baseOperation = glUseProgram,
	cArguments = (6,)
)
[2025-10-04 01:47:45.623] {                 Renderable.py: 183} (              UIMain3DSub:   ERROR) - Unable to use the GL program because:
Traceback (most recent call last):
  File "/Users/dominiklang/Artemotion/scripts/engine3d/core/GLProgram.py", line 131, in use
    pygl.glUseProgram(self._id)
  File "/Users/dominiklang/Artemotion/venv/lib/python3.11/site-packages/OpenGL/error.py", line 230, in glCheckError
    raise self._errorClass(
OpenGL.error.GLError: GLError(
	err = 1282,
	description = b'invalid operation',
	baseOperation = glUseProgram,
	cArguments = (6,)
)
[2025-10-04 01:47:45.631] {                 Renderable.py: 183} (              UIMain3DSub:   ERROR) - Unable to use the GL program because:
Traceback (most recent call last):
  File "/Users/dominiklang/Artemotion/scripts/engine3d/core/GLProgram.py", line 131, in use
    pygl.glUseProgram(self._id)
  File "/Users/dominiklang/Artemotion/venv/lib/python3.11/site-packages/OpenGL/error.py", line 230, in glCheckError
    raise self._errorClass(
OpenGL.error.GLError: GLError(
	err = 1282,
	description = b'invalid operation',
	baseOperation = glUseProgram,
	cArguments = (6,)
)
[2025-10-04 01:47:45.639] {                 Renderable.py: 183} (              UIMain3DSub:   ERROR) - Unable to use the GL program because:
Traceback (most recent call last):
  File "/Users/dominiklang/Artemotion/scripts/engine3d/core/GLProgram.py", line 131, in use
    pygl.glUseProgram(self._id)
  File "/Users/dominiklang/Artemotion/venv/lib/python3.11/site-packages/OpenGL/error.py", line 230, in glCheckError
    raise self._errorClass(
OpenGL.error.GLError: GLError(
	err = 1282,
	description = b'invalid operation',
	baseOperation = glUseProgram,
	cArguments = (6,)
)
[2025-10-04 01:47:45.651] {                 Renderable.py: 183} (              UIMain3DSub:   ERROR) - Unable to use the GL program because:
Traceback (most recent call last):
  File "/Users/dominiklang/Artemotion/scripts/engine3d/core/GLProgram.py", line 131, in use
    pygl.glUseProgram(self._id)
  File "/Users/dominiklang/Artemotion/venv/lib/python3.11/site-packages/OpenGL/error.py", line 230, in glCheckError
    raise self._errorClass(
OpenGL.error.GLError: GLError(
	err = 1282,
	description = b'invalid operation',
	baseOperation = glUseProgram,
	cArguments = (6,)
)
[2025-10-04 01:47:45.656] {                 Renderable.py: 183} (              UIMain3DSub:   ERROR) - Unable to use the GL program because:
Traceback (most recent call last):
  File "/Users/dominiklang/Artemotion/scripts/engine3d/core/GLProgram.py", line 131, in use
    pygl.glUseProgram(self._id)
  File "/Users/dominiklang/Artemotion/venv/lib/python3.11/site-packages/OpenGL/error.py", line 230, in glCheckError
    raise self._errorClass(
OpenGL.error.GLError: GLError(
	err = 1282,
	description = b'invalid operation',
	baseOperation = glUseProgram,
	cArguments = (6,)
)
[2025-10-04 01:47:45.664] {                 Renderable.py: 183} (              UIMain3DSub:   ERROR) - Unable to use the GL program because:
Traceback (most recent call last):
  File "/Users/dominiklang/Artemotion/scripts/engine3d/core/GLProgram.py", line 131, in use
    pygl.glUseProgram(self._id)
  File "/Users/dominiklang/Artemotion/venv/lib/python3.11/site-packages/OpenGL/error.py", line 230, in glCheckError
    raise self._errorClass(
OpenGL.error.GLError: GLError(
	err = 1282,
	description = b'invalid operation',
	baseOperation = glUseProgram,
	cArguments = (6,)
)
[2025-10-04 01:47:45.672] {                 Renderable.py: 183} (              UIMain3DSub:   ERROR) - Unable to use the GL program because:
Traceback (most recent call last):
  File "/Users/dominiklang/Artemotion/scripts/engine3d/core/GLProgram.py", line 131, in use
    pygl.glUseProgram(self._id)
  File "/Users/dominiklang/Artemotion/venv/lib/python3.11/site-packages/OpenGL/error.py", line 230, in glCheckError
    raise self._errorClass(
OpenGL.error.GLError: GLError(
	err = 1282,
	description = b'invalid operation',
	baseOperation = glUseProgram,
	cArguments = (6,)
)
[2025-10-04 01:47:45.689] {                 Renderable.py: 183} (              UIMain3DSub:   ERROR) - Unable to use the GL program because:
Traceback (most recent call last):
  File "/Users/dominiklang/Artemotion/scripts/engine3d/core/GLProgram.py", line 131, in use
    pygl.glUseProgram(self._id)
  File "/Users/dominiklang/Artemotion/venv/lib/python3.11/site-packages/OpenGL/error.py", line 230, in glCheckError
    raise self._errorClass(
OpenGL.error.GLError: GLError(
	err = 1282,
	description = b'invalid operation',
	baseOperation = glUseProgram,
	cArguments = (6,)
)
[2025-10-04 01:47:45.706] {                 Renderable.py: 183} (              UIMain3DSub:   ERROR) - Unable to use the GL program because:
Traceback (most recent call last):
  File "/Users/dominiklang/Artemotion/scripts/engine3d/core/GLProgram.py", line 131, in use
    pygl.glUseProgram(self._id)
  File "/Users/dominiklang/Artemotion/venv/lib/python3.11/site-packages/OpenGL/error.py", line 230, in glCheckError
    raise self._errorClass(
OpenGL.error.GLError: GLError(
	err = 1282,
	description = b'invalid operation',
	baseOperation = glUseProgram,
	cArguments = (6,)
)
[2025-10-04 01:47:45.729] {                 Renderable.py: 183} (              UIMain3DSub:   ERROR) - Unable to use the GL program because:
Traceback (most recent call last):
  File "/Users/dominiklang/Artemotion/scripts/engine3d/core/GLProgram.py", line 131, in use
    pygl.glUseProgram(self._id)
  File "/Users/dominiklang/Artemotion/venv/lib/python3.11/site-packages/OpenGL/error.py", line 230, in glCheckError
    raise self._errorClass(
OpenGL.error.GLError: GLError(
	err = 1282,
	description = b'invalid operation',
	baseOperation = glUseProgram,
	cArguments = (6,)
)
[2025-10-04 01:47:45.745] {                 Renderable.py: 183} (              UIMain3DSub:   ERROR) - Unable to use the GL program because:
Traceback (most recent call last):
  File "/Users/dominiklang/Artemotion/scripts/engine3d/core/GLProgram.py", line 131, in use
    pygl.glUseProgram(self._id)
  File "/Users/dominiklang/Artemotion/venv/lib/python3.11/site-packages/OpenGL/error.py", line 230, in glCheckError
    raise self._errorClass(
OpenGL.error.GLError: GLError(
	err = 1282,
	description = b'invalid operation',
	baseOperation = glUseProgram,
	cArguments = (6,)
)
[2025-10-04 01:47:45.756] {                 Renderable.py: 183} (              UIMain3DSub:   ERROR) - Unable to use the GL program because:
Traceback (most recent call last):
  File "/Users/dominiklang/Artemotion/scripts/engine3d/core/GLProgram.py", line 131, in use
    pygl.glUseProgram(self._id)
  File "/Users/dominiklang/Artemotion/venv/lib/python3.11/site-packages/OpenGL/error.py", line 230, in glCheckError
    raise self._errorClass(
OpenGL.error.GLError: GLError(
	err = 1282,
	description = b'invalid operation',
	baseOperation = glUseProgram,
	cArguments = (6,)
)
[2025-10-04 01:47:45.772] {                 Renderable.py: 183} (              UIMain3DSub:   ERROR) - Unable to use the GL program because:
Traceback (most recent call last):
  File "/Users/dominiklang/Artemotion/scripts/engine3d/core/GLProgram.py", line 131, in use
    pygl.glUseProgram(self._id)
  File "/Users/dominiklang/Artemotion/venv/lib/python3.11/site-packages/OpenGL/error.py", line 230, in glCheckError
    raise self._errorClass(
OpenGL.error.GLError: GLError(
	err = 1282,
	description = b'invalid operation',
	baseOperation = glUseProgram,
	cArguments = (6,)
)
[2025-10-04 01:47:45.798] {                 Renderable.py: 183} (              UIMain3DSub:   ERROR) - Unable to use the GL program because:
Traceback (most recent call last):
  File "/Users/dominiklang/Artemotion/scripts/engine3d/core/GLProgram.py", line 131, in use
    pygl.glUseProgram(self._id)
  File "/Users/dominiklang/Artemotion/venv/lib/python3.11/site-packages/OpenGL/error.py", line 230, in glCheckError
    raise self._errorClass(
OpenGL.error.GLError: GLError(
	err = 1282,
	description = b'invalid operation',
	baseOperation = glUseProgram,
	cArguments = (6,)
)
[2025-10-04 01:47:45.806] {                 Renderable.py: 183} (              UIMain3DSub:   ERROR) - Unable to use the GL program because:
Traceback (most recent call last):
  File "/Users/dominiklang/Artemotion/scripts/engine3d/core/GLProgram.py", line 131, in use
    pygl.glUseProgram(self._id)
  File "/Users/dominiklang/Artemotion/venv/lib/python3.11/site-packages/OpenGL/error.py", line 230, in glCheckError
    raise self._errorClass(
OpenGL.error.GLError: GLError(
	err = 1282,
	description = b'invalid operation',
	baseOperation = glUseProgram,
	cArguments = (6,)
)
[2025-10-04 01:47:45.822] {                 Renderable.py: 183} (              UIMain3DSub:   ERROR) - Unable to use the GL program because:
Traceback (most recent call last):
  File "/Users/dominiklang/Artemotion/scripts/engine3d/core/GLProgram.py", line 131, in use
    pygl.glUseProgram(self._id)
  File "/Users/dominiklang/Artemotion/venv/lib/python3.11/site-packages/OpenGL/error.py", line 230, in glCheckError
    raise self._errorClass(
OpenGL.error.GLError: GLError(
	err = 1282,
	description = b'invalid operation',
	baseOperation = glUseProgram,
	cArguments = (6,)
)
[2025-10-04 01:47:45.839] {                 Renderable.py: 183} (              UIMain3DSub:   ERROR) - Unable to use the GL program because:
Traceback (most recent call last):
  File "/Users/dominiklang/Artemotion/scripts/engine3d/core/GLProgram.py", line 131, in use
    pygl.glUseProgram(self._id)
  File "/Users/dominiklang/Artemotion/venv/lib/python3.11/site-packages/OpenGL/error.py", line 230, in glCheckError
    raise self._errorClass(
OpenGL.error.GLError: GLError(
	err = 1282,
	description = b'invalid operation',
	baseOperation = glUseProgram,
	cArguments = (6,)
)
[2025-10-04 01:47:45.844] {                 Renderable.py: 183} (              UIMain3DSub:   ERROR) - Unable to use the GL program because:
Traceback (most recent call last):
  File "/Users/dominiklang/Artemotion/scripts/engine3d/core/GLProgram.py", line 131, in use
    pygl.glUseProgram(self._id)
  File "/Users/dominiklang/Artemotion/venv/lib/python3.11/site-packages/OpenGL/error.py", line 230, in glCheckError
    raise self._errorClass(
OpenGL.error.GLError: GLError(
	err = 1282,
	description = b'invalid operation',
	baseOperation = glUseProgram,
	cArguments = (6,)
)
[2025-10-04 01:47:45.855] {                 Renderable.py: 183} (              UIMain3DSub:   ERROR) - Unable to use the GL program because:
Traceback (most recent call last):
  File "/Users/dominiklang/Artemotion/scripts/engine3d/core/GLProgram.py", line 131, in use
    pygl.glUseProgram(self._id)
  File "/Users/dominiklang/Artemotion/venv/lib/python3.11/site-packages/OpenGL/error.py", line 230, in glCheckError
    raise self._errorClass(
OpenGL.error.GLError: GLError(
	err = 1282,
	description = b'invalid operation',
	baseOperation = glUseProgram,
	cArguments = (6,)
)
[2025-10-04 01:47:45.862] {                 Renderable.py: 183} (              UIMain3DSub:   ERROR) - Unable to use the GL program because:
Traceback (most recent call last):
  File "/Users/dominiklang/Artemotion/scripts/engine3d/core/GLProgram.py", line 131, in use
    pygl.glUseProgram(self._id)
  File "/Users/dominiklang/Artemotion/venv/lib/python3.11/site-packages/OpenGL/error.py", line 230, in glCheckError
    raise self._errorClass(
OpenGL.error.GLError: GLError(
	err = 1282,
	description = b'invalid operation',
	baseOperation = glUseProgram,
	cArguments = (6,)
)
[2025-10-04 01:47:45.872] {                 Renderable.py: 183} (              UIMain3DSub:   ERROR) - Unable to use the GL program because:
Traceback (most recent call last):
  File "/Users/dominiklang/Artemotion/scripts/engine3d/core/GLProgram.py", line 131, in use
    pygl.glUseProgram(self._id)
  File "/Users/dominiklang/Artemotion/venv/lib/python3.11/site-packages/OpenGL/error.py", line 230, in glCheckError
    raise self._errorClass(
OpenGL.error.GLError: GLError(
	err = 1282,
	description = b'invalid operation',
	baseOperation = glUseProgram,
	cArguments = (6,)
)
[2025-10-04 01:47:45.891] {                 Renderable.py: 183} (              UIMain3DSub:   ERROR) - Unable to use the GL program because:
Traceback (most recent call last):
  File "/Users/dominiklang/Artemotion/scripts/engine3d/core/GLProgram.py", line 131, in use
    pygl.glUseProgram(self._id)
  File "/Users/dominiklang/Artemotion/venv/lib/python3.11/site-packages/OpenGL/error.py", line 230, in glCheckError
    raise self._errorClass(
OpenGL.error.GLError: GLError(
	err = 1282,
	description = b'invalid operation',
	baseOperation = glUseProgram,
	cArguments = (6,)
)
[2025-10-04 01:47:45.900] {                 Renderable.py: 183} (              UIMain3DSub:   ERROR) - Unable to use the GL program because:
Traceback (most recent call last):
  File "/Users/dominiklang/Artemotion/scripts/engine3d/core/GLProgram.py", line 131, in use
    pygl.glUseProgram(self._id)
  File "/Users/dominiklang/Artemotion/venv/lib/python3.11/site-packages/OpenGL/error.py", line 230, in glCheckError
    raise self._errorClass(
OpenGL.error.GLError: GLError(
	err = 1282,
	description = b'invalid operation',
	baseOperation = glUseProgram,
	cArguments = (6,)
)
[2025-10-04 01:47:45.905] {                 Renderable.py: 183} (              UIMain3DSub:   ERROR) - Unable to use the GL program because:
Traceback (most recent call last):
  File "/Users/dominiklang/Artemotion/scripts/engine3d/core/GLProgram.py", line 131, in use
    pygl.glUseProgram(self._id)
  File "/Users/dominiklang/Artemotion/venv/lib/python3.11/site-packages/OpenGL/error.py", line 230, in glCheckError
    raise self._errorClass(
OpenGL.error.GLError: GLError(
	err = 1282,
	description = b'invalid operation',
	baseOperation = glUseProgram,
	cArguments = (6,)
)
[2025-10-04 01:47:45.914] {                 Renderable.py: 183} (              UIMain3DSub:   ERROR) - Unable to use the GL program because:
Traceback (most recent call last):
  File "/Users/dominiklang/Artemotion/scripts/engine3d/core/GLProgram.py", line 131, in use
    pygl.glUseProgram(self._id)
  File "/Users/dominiklang/Artemotion/venv/lib/python3.11/site-packages/OpenGL/error.py", line 230, in glCheckError
    raise self._errorClass(
OpenGL.error.GLError: GLError(
	err = 1282,
	description = b'invalid operation',
	baseOperation = glUseProgram,
	cArguments = (6,)
)
[2025-10-04 01:47:45.922] {                 Renderable.py: 183} (              UIMain3DSub:   ERROR) - Unable to use the GL program because:
Traceback (most recent call last):
  File "/Users/dominiklang/Artemotion/scripts/engine3d/core/GLProgram.py", line 131, in use
    pygl.glUseProgram(self._id)
  File "/Users/dominiklang/Artemotion/venv/lib/python3.11/site-packages/OpenGL/error.py", line 230, in glCheckError
    raise self._errorClass(
OpenGL.error.GLError: GLError(
	err = 1282,
	description = b'invalid operation',
	baseOperation = glUseProgram,
	cArguments = (6,)
)
[2025-10-04 01:47:45.931] {                 Renderable.py: 183} (              UIMain3DSub:   ERROR) - Unable to use the GL program because:
Traceback (most recent call last):
  File "/Users/dominiklang/Artemotion/scripts/engine3d/core/GLProgram.py", line 131, in use
    pygl.glUseProgram(self._id)
  File "/Users/dominiklang/Artemotion/venv/lib/python3.11/site-packages/OpenGL/error.py", line 230, in glCheckError
    raise self._errorClass(
OpenGL.error.GLError: GLError(
	err = 1282,
	description = b'invalid operation',
	baseOperation = glUseProgram,
	cArguments = (6,)
)
[2025-10-04 01:47:45.939] {                 Renderable.py: 183} (              UIMain3DSub:   ERROR) - Unable to use the GL program because:
Traceback (most recent call last):
  File "/Users/dominiklang/Artemotion/scripts/engine3d/core/GLProgram.py", line 131, in use
    pygl.glUseProgram(self._id)
  File "/Users/dominiklang/Artemotion/venv/lib/python3.11/site-packages/OpenGL/error.py", line 230, in glCheckError
    raise self._errorClass(
OpenGL.error.GLError: GLError(
	err = 1282,
	description = b'invalid operation',
	baseOperation = glUseProgram,
	cArguments = (6,)
)
[2025-10-04 01:47:45.943] {                 Renderable.py: 183} (              UIMain3DSub:   ERROR) - Unable to use the GL program because:
Traceback (most recent call last):
  File "/Users/dominiklang/Artemotion/scripts/engine3d/core/GLProgram.py", line 131, in use
    pygl.glUseProgram(self._id)
  File "/Users/dominiklang/Artemotion/venv/lib/python3.11/site-packages/OpenGL/error.py", line 230, in glCheckError
    raise self._errorClass(
OpenGL.error.GLError: GLError(
	err = 1282,
	description = b'invalid operation',
	baseOperation = glUseProgram,
	cArguments = (6,)
)
[2025-10-04 01:47:45.955] {                 Renderable.py: 183} (              UIMain3DSub:   ERROR) - Unable to use the GL program because:
Traceback (most recent call last):
  File "/Users/dominiklang/Artemotion/scripts/engine3d/core/GLProgram.py", line 131, in use
    pygl.glUseProgram(self._id)
  File "/Users/dominiklang/Artemotion/venv/lib/python3.11/site-packages/OpenGL/error.py", line 230, in glCheckError
    raise self._errorClass(
OpenGL.error.GLError: GLError(
	err = 1282,
	description = b'invalid operation',
	baseOperation = glUseProgram,
	cArguments = (6,)
)
[2025-10-04 01:47:46.011] {                 Renderable.py: 183} (              UIMain3DSub:   ERROR) - Unable to use the GL program because:
Traceback (most recent call last):
  File "/Users/dominiklang/Artemotion/scripts/engine3d/core/GLProgram.py", line 131, in use
    pygl.glUseProgram(self._id)
  File "/Users/dominiklang/Artemotion/venv/lib/python3.11/site-packages/OpenGL/error.py", line 230, in glCheckError
    raise self._errorClass(
OpenGL.error.GLError: GLError(
	err = 1282,
	description = b'invalid operation',
	baseOperation = glUseProgram,
	cArguments = (6,)
)
[2025-10-04 01:47:46.022] {                 Renderable.py: 183} (              UIMain3DSub:   ERROR) - Unable to use the GL program because:
Traceback (most recent call last):
  File "/Users/dominiklang/Artemotion/scripts/engine3d/core/GLProgram.py", line 131, in use
    pygl.glUseProgram(self._id)
  File "/Users/dominiklang/Artemotion/venv/lib/python3.11/site-packages/OpenGL/error.py", line 230, in glCheckError
    raise self._errorClass(
OpenGL.error.GLError: GLError(
	err = 1282,
	description = b'invalid operation',
	baseOperation = glUseProgram,
	cArguments = (6,)
)
[2025-10-04 01:47:46.377] {                 Renderable.py: 183} (              UIMain3DSub:   ERROR) - Unable to use the GL program because:
Traceback (most recent call last):
  File "/Users/dominiklang/Artemotion/scripts/engine3d/core/GLProgram.py", line 131, in use
    pygl.glUseProgram(self._id)
  File "/Users/dominiklang/Artemotion/venv/lib/python3.11/site-packages/OpenGL/error.py", line 230, in glCheckError
    raise self._errorClass(
OpenGL.error.GLError: GLError(
	err = 1282,
	description = b'invalid operation',
	baseOperation = glUseProgram,
	cArguments = (6,)
)
[2025-10-04 01:47:46.472] {                 Renderable.py: 183} (              UIMain3DSub:   ERROR) - Unable to use the GL program because:
Traceback (most recent call last):
  File "/Users/dominiklang/Artemotion/scripts/engine3d/core/GLProgram.py", line 131, in use
    pygl.glUseProgram(self._id)
  File "/Users/dominiklang/Artemotion/venv/lib/python3.11/site-packages/OpenGL/error.py", line 230, in glCheckError
    raise self._errorClass(
OpenGL.error.GLError: GLError(
	err = 1282,
	description = b'invalid operation',
	baseOperation = glUseProgram,
	cArguments = (6,)
)
[2025-10-04 01:47:46.478] {                 Renderable.py: 183} (              UIMain3DSub:   ERROR) - Unable to use the GL program because:
Traceback (most recent call last):
  File "/Users/dominiklang/Artemotion/scripts/engine3d/core/GLProgram.py", line 131, in use
    pygl.glUseProgram(self._id)
  File "/Users/dominiklang/Artemotion/venv/lib/python3.11/site-packages/OpenGL/error.py", line 230, in glCheckError
    raise self._errorClass(
OpenGL.error.GLError: GLError(
	err = 1282,
	description = b'invalid operation',
	baseOperation = glUseProgram,
	cArguments = (6,)
)
[2025-10-04 01:47:46.489] {                 Renderable.py: 183} (              UIMain3DSub:   ERROR) - Unable to use the GL program because:
Traceback (most recent call last):
  File "/Users/dominiklang/Artemotion/scripts/engine3d/core/GLProgram.py", line 131, in use
    pygl.glUseProgram(self._id)
  File "/Users/dominiklang/Artemotion/venv/lib/python3.11/site-packages/OpenGL/error.py", line 230, in glCheckError
    raise self._errorClass(
OpenGL.error.GLError: GLError(
	err = 1282,
	description = b'invalid operation',
	baseOperation = glUseProgram,
	cArguments = (6,)
)
[2025-10-04 01:47:46.493] {                 Renderable.py: 183} (              UIMain3DSub:   ERROR) - Unable to use the GL program because:
Traceback (most recent call last):
  File "/Users/dominiklang/Artemotion/scripts/engine3d/core/GLProgram.py", line 131, in use
    pygl.glUseProgram(self._id)
  File "/Users/dominiklang/Artemotion/venv/lib/python3.11/site-packages/OpenGL/error.py", line 230, in glCheckError
    raise self._errorClass(
OpenGL.error.GLError: GLError(
	err = 1282,
	description = b'invalid operation',
	baseOperation = glUseProgram,
	cArguments = (6,)
)
[2025-10-04 01:47:46.519] {                 Renderable.py: 183} (              UIMain3DSub:   ERROR) - Unable to use the GL program because:
Traceback (most recent call last):
  File "/Users/dominiklang/Artemotion/scripts/engine3d/core/GLProgram.py", line 131, in use
    pygl.glUseProgram(self._id)
  File "/Users/dominiklang/Artemotion/venv/lib/python3.11/site-packages/OpenGL/error.py", line 230, in glCheckError
    raise self._errorClass(
OpenGL.error.GLError: GLError(
	err = 1282,
	description = b'invalid operation',
	baseOperation = glUseProgram,
	cArguments = (6,)
)
[2025-10-04 01:47:46.522] {                 Renderable.py: 183} (              UIMain3DSub:   ERROR) - Unable to use the GL program because:
Traceback (most recent call last):
  File "/Users/dominiklang/Artemotion/scripts/engine3d/core/GLProgram.py", line 131, in use
    pygl.glUseProgram(self._id)
  File "/Users/dominiklang/Artemotion/venv/lib/python3.11/site-packages/OpenGL/error.py", line 230, in glCheckError
    raise self._errorClass(
OpenGL.error.GLError: GLError(
	err = 1282,
	description = b'invalid operation',
	baseOperation = glUseProgram,
	cArguments = (6,)
)
[2025-10-04 01:47:46.539] {                 Renderable.py: 183} (              UIMain3DSub:   ERROR) - Unable to use the GL program because:
Traceback (most recent call last):
  File "/Users/dominiklang/Artemotion/scripts/engine3d/core/GLProgram.py", line 131, in use
    pygl.glUseProgram(self._id)
  File "/Users/dominiklang/Artemotion/venv/lib/python3.11/site-packages/OpenGL/error.py", line 230, in glCheckError
    raise self._errorClass(
OpenGL.error.GLError: GLError(
	err = 1282,
	description = b'invalid operation',
	baseOperation = glUseProgram,
	cArguments = (6,)
)
[2025-10-04 01:47:46.555] {                 Renderable.py: 183} (              UIMain3DSub:   ERROR) - Unable to use the GL program because:
Traceback (most recent call last):
  File "/Users/dominiklang/Artemotion/scripts/engine3d/core/GLProgram.py", line 131, in use
    pygl.glUseProgram(self._id)
  File "/Users/dominiklang/Artemotion/venv/lib/python3.11/site-packages/OpenGL/error.py", line 230, in glCheckError
    raise self._errorClass(
OpenGL.error.GLError: GLError(
	err = 1282,
	description = b'invalid operation',
	baseOperation = glUseProgram,
	cArguments = (6,)
)
[2025-10-04 01:47:46.572] {                 Renderable.py: 183} (              UIMain3DSub:   ERROR) - Unable to use the GL program because:
Traceback (most recent call last):
  File "/Users/dominiklang/Artemotion/scripts/engine3d/core/GLProgram.py", line 131, in use
    pygl.glUseProgram(self._id)
  File "/Users/dominiklang/Artemotion/venv/lib/python3.11/site-packages/OpenGL/error.py", line 230, in glCheckError
    raise self._errorClass(
OpenGL.error.GLError: GLError(
	err = 1282,
	description = b'invalid operation',
	baseOperation = glUseProgram,
	cArguments = (6,)
)
[2025-10-04 01:47:46.589] {                 Renderable.py: 183} (              UIMain3DSub:   ERROR) - Unable to use the GL program because:
Traceback (most recent call last):
  File "/Users/dominiklang/Artemotion/scripts/engine3d/core/GLProgram.py", line 131, in use
    pygl.glUseProgram(self._id)
  File "/Users/dominiklang/Artemotion/venv/lib/python3.11/site-packages/OpenGL/error.py", line 230, in glCheckError
    raise self._errorClass(
OpenGL.error.GLError: GLError(
	err = 1282,
	description = b'invalid operation',
	baseOperation = glUseProgram,
	cArguments = (6,)
)
[2025-10-04 01:47:46.605] {                 Renderable.py: 183} (              UIMain3DSub:   ERROR) - Unable to use the GL program because:
Traceback (most recent call last):
  File "/Users/dominiklang/Artemotion/scripts/engine3d/core/GLProgram.py", line 131, in use
    pygl.glUseProgram(self._id)
  File "/Users/dominiklang/Artemotion/venv/lib/python3.11/site-packages/OpenGL/error.py", line 230, in glCheckError
    raise self._errorClass(
OpenGL.error.GLError: GLError(
	err = 1282,
	description = b'invalid operation',
	baseOperation = glUseProgram,
	cArguments = (6,)
)
[2025-10-04 01:47:46.622] {                 Renderable.py: 183} (              UIMain3DSub:   ERROR) - Unable to use the GL program because:
Traceback (most recent call last):
  File "/Users/dominiklang/Artemotion/scripts/engine3d/core/GLProgram.py", line 131, in use
    pygl.glUseProgram(self._id)
  File "/Users/dominiklang/Artemotion/venv/lib/python3.11/site-packages/OpenGL/error.py", line 230, in glCheckError
    raise self._errorClass(
OpenGL.error.GLError: GLError(
	err = 1282,
	description = b'invalid operation',
	baseOperation = glUseProgram,
	cArguments = (6,)
)
[2025-10-04 01:47:46.639] {                 Renderable.py: 183} (              UIMain3DSub:   ERROR) - Unable to use the GL program because:
Traceback (most recent call last):
  File "/Users/dominiklang/Artemotion/scripts/engine3d/core/GLProgram.py", line 131, in use
    pygl.glUseProgram(self._id)
  File "/Users/dominiklang/Artemotion/venv/lib/python3.11/site-packages/OpenGL/error.py", line 230, in glCheckError
    raise self._errorClass(
OpenGL.error.GLError: GLError(
	err = 1282,
	description = b'invalid operation',
	baseOperation = glUseProgram,
	cArguments = (6,)
)
[2025-10-04 01:47:46.655] {                 Renderable.py: 183} (              UIMain3DSub:   ERROR) - Unable to use the GL program because:
Traceback (most recent call last):
  File "/Users/dominiklang/Artemotion/scripts/engine3d/core/GLProgram.py", line 131, in use
    pygl.glUseProgram(self._id)
  File "/Users/dominiklang/Artemotion/venv/lib/python3.11/site-packages/OpenGL/error.py", line 230, in glCheckError
    raise self._errorClass(
OpenGL.error.GLError: GLError(
	err = 1282,
	description = b'invalid operation',
	baseOperation = glUseProgram,
	cArguments = (6,)
)
[2025-10-04 01:47:46.672] {                 Renderable.py: 183} (              UIMain3DSub:   ERROR) - Unable to use the GL program because:
Traceback (most recent call last):
  File "/Users/dominiklang/Artemotion/scripts/engine3d/core/GLProgram.py", line 131, in use
    pygl.glUseProgram(self._id)
  File "/Users/dominiklang/Artemotion/venv/lib/python3.11/site-packages/OpenGL/error.py", line 230, in glCheckError
    raise self._errorClass(
OpenGL.error.GLError: GLError(
	err = 1282,
	description = b'invalid operation',
	baseOperation = glUseProgram,
	cArguments = (6,)
)
[2025-10-04 01:47:46.689] {                 Renderable.py: 183} (              UIMain3DSub:   ERROR) - Unable to use the GL program because:
Traceback (most recent call last):
  File "/Users/dominiklang/Artemotion/scripts/engine3d/core/GLProgram.py", line 131, in use
    pygl.glUseProgram(self._id)
  File "/Users/dominiklang/Artemotion/venv/lib/python3.11/site-packages/OpenGL/error.py", line 230, in glCheckError
    raise self._errorClass(
OpenGL.error.GLError: GLError(
	err = 1282,
	description = b'invalid operation',
	baseOperation = glUseProgram,
	cArguments = (6,)
)
[2025-10-04 01:47:46.705] {                 Renderable.py: 183} (              UIMain3DSub:   ERROR) - Unable to use the GL program because:
Traceback (most recent call last):
  File "/Users/dominiklang/Artemotion/scripts/engine3d/core/GLProgram.py", line 131, in use
    pygl.glUseProgram(self._id)
  File "/Users/dominiklang/Artemotion/venv/lib/python3.11/site-packages/OpenGL/error.py", line 230, in glCheckError
    raise self._errorClass(
OpenGL.error.GLError: GLError(
	err = 1282,
	description = b'invalid operation',
	baseOperation = glUseProgram,
	cArguments = (6,)
)
[2025-10-04 01:47:47.172] {                 Renderable.py: 183} (              UIMain3DSub:   ERROR) - Unable to use the GL program because:
Traceback (most recent call last):
  File "/Users/dominiklang/Artemotion/scripts/engine3d/core/GLProgram.py", line 131, in use
    pygl.glUseProgram(self._id)
  File "/Users/dominiklang/Artemotion/venv/lib/python3.11/site-packages/OpenGL/error.py", line 230, in glCheckError
    raise self._errorClass(
OpenGL.error.GLError: GLError(
	err = 1282,
	description = b'invalid operation',
	baseOperation = glUseProgram,
	cArguments = (6,)
)
[2025-10-04 01:47:47.175] {                 Renderable.py: 183} (              UIMain3DSub:   ERROR) - Unable to use the GL program because:
Traceback (most recent call last):
  File "/Users/dominiklang/Artemotion/scripts/engine3d/core/GLProgram.py", line 131, in use
    pygl.glUseProgram(self._id)
  File "/Users/dominiklang/Artemotion/venv/lib/python3.11/site-packages/OpenGL/error.py", line 230, in glCheckError
    raise self._errorClass(
OpenGL.error.GLError: GLError(
	err = 1282,
	description = b'invalid operation',
	baseOperation = glUseProgram,
	cArguments = (6,)
)
[2025-10-04 01:47:47.433] {                 Renderable.py: 183} (              UIMain3DSub:   ERROR) - Unable to use the GL program because:
Traceback (most recent call last):
  File "/Users/dominiklang/Artemotion/scripts/engine3d/core/GLProgram.py", line 131, in use
    pygl.glUseProgram(self._id)
  File "/Users/dominiklang/Artemotion/venv/lib/python3.11/site-packages/OpenGL/error.py", line 230, in glCheckError
    raise self._errorClass(
OpenGL.error.GLError: GLError(
	err = 1282,
	description = b'invalid operation',
	baseOperation = glUseProgram,
	cArguments = (6,)
)
[2025-10-04 01:47:47.436] {                 Renderable.py: 183} (              UIMain3DSub:   ERROR) - Unable to use the GL program because:
Traceback (most recent call last):
  File "/Users/dominiklang/Artemotion/scripts/engine3d/core/GLProgram.py", line 131, in use
    pygl.glUseProgram(self._id)
  File "/Users/dominiklang/Artemotion/venv/lib/python3.11/site-packages/OpenGL/error.py", line 230, in glCheckError
    raise self._errorClass(
OpenGL.error.GLError: GLError(
	err = 1282,
	description = b'invalid operation',
	baseOperation = glUseProgram,
	cArguments = (6,)
)
[2025-10-04 01:47:47.572] {                 Renderable.py: 183} (              UIMain3DSub:   ERROR) - Unable to use the GL program because:
Traceback (most recent call last):
  File "/Users/dominiklang/Artemotion/scripts/engine3d/core/GLProgram.py", line 131, in use
    pygl.glUseProgram(self._id)
  File "/Users/dominiklang/Artemotion/venv/lib/python3.11/site-packages/OpenGL/error.py", line 230, in glCheckError
    raise self._errorClass(
OpenGL.error.GLError: GLError(
	err = 1282,
	description = b'invalid operation',
	baseOperation = glUseProgram,
	cArguments = (6,)
)
[2025-10-04 01:47:47.574] {                 Renderable.py: 183} (              UIMain3DSub:   ERROR) - Unable to use the GL program because:
Traceback (most recent call last):
  File "/Users/dominiklang/Artemotion/scripts/engine3d/core/GLProgram.py", line 131, in use
    pygl.glUseProgram(self._id)
  File "/Users/dominiklang/Artemotion/venv/lib/python3.11/site-packages/OpenGL/error.py", line 230, in glCheckError
    raise self._errorClass(
OpenGL.error.GLError: GLError(
	err = 1282,
	description = b'invalid operation',
	baseOperation = glUseProgram,
	cArguments = (6,)
)
[2025-10-04 01:47:47.606] {                 Renderable.py: 183} (              UIMain3DSub:   ERROR) - Unable to use the GL program because:
Traceback (most recent call last):
  File "/Users/dominiklang/Artemotion/scripts/engine3d/core/GLProgram.py", line 131, in use
    pygl.glUseProgram(self._id)
  File "/Users/dominiklang/Artemotion/venv/lib/python3.11/site-packages/OpenGL/error.py", line 230, in glCheckError
    raise self._errorClass(
OpenGL.error.GLError: GLError(
	err = 1282,
	description = b'invalid operation',
	baseOperation = glUseProgram,
	cArguments = (6,)
)
[2025-10-04 01:47:47.610] {                 Renderable.py: 183} (              UIMain3DSub:   ERROR) - Unable to use the GL program because:
Traceback (most recent call last):
  File "/Users/dominiklang/Artemotion/scripts/engine3d/core/GLProgram.py", line 131, in use
    pygl.glUseProgram(self._id)
  File "/Users/dominiklang/Artemotion/venv/lib/python3.11/site-packages/OpenGL/error.py", line 230, in glCheckError
    raise self._errorClass(
OpenGL.error.GLError: GLError(
	err = 1282,
	description = b'invalid operation',
	baseOperation = glUseProgram,
	cArguments = (6,)
)
[2025-10-04 01:47:48.281] {                 Renderable.py: 183} (              UIMain3DSub:   ERROR) - Unable to use the GL program because:
Traceback (most recent call last):
  File "/Users/dominiklang/Artemotion/scripts/engine3d/core/GLProgram.py", line 131, in use
    pygl.glUseProgram(self._id)
  File "/Users/dominiklang/Artemotion/venv/lib/python3.11/site-packages/OpenGL/error.py", line 230, in glCheckError
    raise self._errorClass(
OpenGL.error.GLError: GLError(
	err = 1282,
	description = b'invalid operation',
	baseOperation = glUseProgram,
	cArguments = (6,)
)
[2025-10-04 01:47:48.289] {                 Renderable.py: 183} (              UIMain3DSub:   ERROR) - Unable to use the GL program because:
Traceback (most recent call last):
  File "/Users/dominiklang/Artemotion/scripts/engine3d/core/GLProgram.py", line 131, in use
    pygl.glUseProgram(self._id)
  File "/Users/dominiklang/Artemotion/venv/lib/python3.11/site-packages/OpenGL/error.py", line 230, in glCheckError
    raise self._errorClass(
OpenGL.error.GLError: GLError(
	err = 1282,
	description = b'invalid operation',
	baseOperation = glUseProgram,
	cArguments = (6,)
)
[2025-10-04 01:47:48.348] {                 Renderable.py: 183} (              UIMain3DSub:   ERROR) - Unable to use the GL program because:
Traceback (most recent call last):
  File "/Users/dominiklang/Artemotion/scripts/engine3d/core/GLProgram.py", line 131, in use
    pygl.glUseProgram(self._id)
  File "/Users/dominiklang/Artemotion/venv/lib/python3.11/site-packages/OpenGL/error.py", line 230, in glCheckError
    raise self._errorClass(
OpenGL.error.GLError: GLError(
	err = 1282,
	description = b'invalid operation',
	baseOperation = glUseProgram,
	cArguments = (6,)
)
[2025-10-04 01:47:48.355] {                 Renderable.py: 183} (              UIMain3DSub:   ERROR) - Unable to use the GL program because:
Traceback (most recent call last):
  File "/Users/dominiklang/Artemotion/scripts/engine3d/core/GLProgram.py", line 131, in use
    pygl.glUseProgram(self._id)
  File "/Users/dominiklang/Artemotion/venv/lib/python3.11/site-packages/OpenGL/error.py", line 230, in glCheckError
    raise self._errorClass(
OpenGL.error.GLError: GLError(
	err = 1282,
	description = b'invalid operation',
	baseOperation = glUseProgram,
	cArguments = (6,)
)
[2025-10-04 01:47:48.362] {                 Renderable.py: 183} (              UIMain3DSub:   ERROR) - Unable to use the GL program because:
Traceback (most recent call last):
  File "/Users/dominiklang/Artemotion/scripts/engine3d/core/GLProgram.py", line 131, in use
    pygl.glUseProgram(self._id)
  File "/Users/dominiklang/Artemotion/venv/lib/python3.11/site-packages/OpenGL/error.py", line 230, in glCheckError
    raise self._errorClass(
OpenGL.error.GLError: GLError(
	err = 1282,
	description = b'invalid operation',
	baseOperation = glUseProgram,
	cArguments = (6,)
)
[2025-10-04 01:47:48.372] {                 Renderable.py: 183} (              UIMain3DSub:   ERROR) - Unable to use the GL program because:
Traceback (most recent call last):
  File "/Users/dominiklang/Artemotion/scripts/engine3d/core/GLProgram.py", line 131, in use
    pygl.glUseProgram(self._id)
  File "/Users/dominiklang/Artemotion/venv/lib/python3.11/site-packages/OpenGL/error.py", line 230, in glCheckError
    raise self._errorClass(
OpenGL.error.GLError: GLError(
	err = 1282,
	description = b'invalid operation',
	baseOperation = glUseProgram,
	cArguments = (6,)
)
[2025-10-04 01:47:48.395] {                 Renderable.py: 183} (              UIMain3DSub:   ERROR) - Unable to use the GL program because:
Traceback (most recent call last):
  File "/Users/dominiklang/Artemotion/scripts/engine3d/core/GLProgram.py", line 131, in use
    pygl.glUseProgram(self._id)
  File "/Users/dominiklang/Artemotion/venv/lib/python3.11/site-packages/OpenGL/error.py", line 230, in glCheckError
    raise self._errorClass(
OpenGL.error.GLError: GLError(
	err = 1282,
	description = b'invalid operation',
	baseOperation = glUseProgram,
	cArguments = (6,)
)
[2025-10-04 01:47:48.407] {                 Renderable.py: 183} (              UIMain3DSub:   ERROR) - Unable to use the GL program because:
Traceback (most recent call last):
  File "/Users/dominiklang/Artemotion/scripts/engine3d/core/GLProgram.py", line 131, in use
    pygl.glUseProgram(self._id)
  File "/Users/dominiklang/Artemotion/venv/lib/python3.11/site-packages/OpenGL/error.py", line 230, in glCheckError
    raise self._errorClass(
OpenGL.error.GLError: GLError(
	err = 1282,
	description = b'invalid operation',
	baseOperation = glUseProgram,
	cArguments = (6,)
)
[2025-10-04 01:47:48.422] {                 Renderable.py: 183} (              UIMain3DSub:   ERROR) - Unable to use the GL program because:
Traceback (most recent call last):
  File "/Users/dominiklang/Artemotion/scripts/engine3d/core/GLProgram.py", line 131, in use
    pygl.glUseProgram(self._id)
  File "/Users/dominiklang/Artemotion/venv/lib/python3.11/site-packages/OpenGL/error.py", line 230, in glCheckError
    raise self._errorClass(
OpenGL.error.GLError: GLError(
	err = 1282,
	description = b'invalid operation',
	baseOperation = glUseProgram,
	cArguments = (6,)
)
[2025-10-04 01:47:48.439] {                 Renderable.py: 183} (              UIMain3DSub:   ERROR) - Unable to use the GL program because:
Traceback (most recent call last):
  File "/Users/dominiklang/Artemotion/scripts/engine3d/core/GLProgram.py", line 131, in use
    pygl.glUseProgram(self._id)
  File "/Users/dominiklang/Artemotion/venv/lib/python3.11/site-packages/OpenGL/error.py", line 230, in glCheckError
    raise self._errorClass(
OpenGL.error.GLError: GLError(
	err = 1282,
	description = b'invalid operation',
	baseOperation = glUseProgram,
	cArguments = (6,)
)
[2025-10-04 01:47:48.463] {                 Renderable.py: 183} (              UIMain3DSub:   ERROR) - Unable to use the GL program because:
Traceback (most recent call last):
  File "/Users/dominiklang/Artemotion/scripts/engine3d/core/GLProgram.py", line 131, in use
    pygl.glUseProgram(self._id)
  File "/Users/dominiklang/Artemotion/venv/lib/python3.11/site-packages/OpenGL/error.py", line 230, in glCheckError
    raise self._errorClass(
OpenGL.error.GLError: GLError(
	err = 1282,
	description = b'invalid operation',
	baseOperation = glUseProgram,
	cArguments = (6,)
)
[2025-10-04 01:47:48.472] {                 Renderable.py: 183} (              UIMain3DSub:   ERROR) - Unable to use the GL program because:
Traceback (most recent call last):
  File "/Users/dominiklang/Artemotion/scripts/engine3d/core/GLProgram.py", line 131, in use
    pygl.glUseProgram(self._id)
  File "/Users/dominiklang/Artemotion/venv/lib/python3.11/site-packages/OpenGL/error.py", line 230, in glCheckError
    raise self._errorClass(
OpenGL.error.GLError: GLError(
	err = 1282,
	description = b'invalid operation',
	baseOperation = glUseProgram,
	cArguments = (6,)
)
[2025-10-04 01:47:48.489] {                 Renderable.py: 183} (              UIMain3DSub:   ERROR) - Unable to use the GL program because:
Traceback (most recent call last):
  File "/Users/dominiklang/Artemotion/scripts/engine3d/core/GLProgram.py", line 131, in use
    pygl.glUseProgram(self._id)
  File "/Users/dominiklang/Artemotion/venv/lib/python3.11/site-packages/OpenGL/error.py", line 230, in glCheckError
    raise self._errorClass(
OpenGL.error.GLError: GLError(
	err = 1282,
	description = b'invalid operation',
	baseOperation = glUseProgram,
	cArguments = (6,)
)
[2025-10-04 01:47:48.506] {                 Renderable.py: 183} (              UIMain3DSub:   ERROR) - Unable to use the GL program because:
Traceback (most recent call last):
  File "/Users/dominiklang/Artemotion/scripts/engine3d/core/GLProgram.py", line 131, in use
    pygl.glUseProgram(self._id)
  File "/Users/dominiklang/Artemotion/venv/lib/python3.11/site-packages/OpenGL/error.py", line 230, in glCheckError
    raise self._errorClass(
OpenGL.error.GLError: GLError(
	err = 1282,
	description = b'invalid operation',
	baseOperation = glUseProgram,
	cArguments = (6,)
)
[2025-10-04 01:47:48.522] {                 Renderable.py: 183} (              UIMain3DSub:   ERROR) - Unable to use the GL program because:
Traceback (most recent call last):
  File "/Users/dominiklang/Artemotion/scripts/engine3d/core/GLProgram.py", line 131, in use
    pygl.glUseProgram(self._id)
  File "/Users/dominiklang/Artemotion/venv/lib/python3.11/site-packages/OpenGL/error.py", line 230, in glCheckError
    raise self._errorClass(
OpenGL.error.GLError: GLError(
	err = 1282,
	description = b'invalid operation',
	baseOperation = glUseProgram,
	cArguments = (6,)
)
[2025-10-04 01:47:48.539] {                 Renderable.py: 183} (              UIMain3DSub:   ERROR) - Unable to use the GL program because:
Traceback (most recent call last):
  File "/Users/dominiklang/Artemotion/scripts/engine3d/core/GLProgram.py", line 131, in use
    pygl.glUseProgram(self._id)
  File "/Users/dominiklang/Artemotion/venv/lib/python3.11/site-packages/OpenGL/error.py", line 230, in glCheckError
    raise self._errorClass(
OpenGL.error.GLError: GLError(
	err = 1282,
	description = b'invalid operation',
	baseOperation = glUseProgram,
	cArguments = (6,)
)
[2025-10-04 01:47:48.555] {                 Renderable.py: 183} (              UIMain3DSub:   ERROR) - Unable to use the GL program because:
Traceback (most recent call last):
  File "/Users/dominiklang/Artemotion/scripts/engine3d/core/GLProgram.py", line 131, in use
    pygl.glUseProgram(self._id)
  File "/Users/dominiklang/Artemotion/venv/lib/python3.11/site-packages/OpenGL/error.py", line 230, in glCheckError
    raise self._errorClass(
OpenGL.error.GLError: GLError(
	err = 1282,
	description = b'invalid operation',
	baseOperation = glUseProgram,
	cArguments = (6,)
)
[2025-10-04 01:47:48.560] {                 Renderable.py: 183} (              UIMain3DSub:   ERROR) - Unable to use the GL program because:
Traceback (most recent call last):
  File "/Users/dominiklang/Artemotion/scripts/engine3d/core/GLProgram.py", line 131, in use
    pygl.glUseProgram(self._id)
  File "/Users/dominiklang/Artemotion/venv/lib/python3.11/site-packages/OpenGL/error.py", line 230, in glCheckError
    raise self._errorClass(
OpenGL.error.GLError: GLError(
	err = 1282,
	description = b'invalid operation',
	baseOperation = glUseProgram,
	cArguments = (6,)
)
[2025-10-04 01:47:48.572] {                 Renderable.py: 183} (              UIMain3DSub:   ERROR) - Unable to use the GL program because:
Traceback (most recent call last):
  File "/Users/dominiklang/Artemotion/scripts/engine3d/core/GLProgram.py", line 131, in use
    pygl.glUseProgram(self._id)
  File "/Users/dominiklang/Artemotion/venv/lib/python3.11/site-packages/OpenGL/error.py", line 230, in glCheckError
    raise self._errorClass(
OpenGL.error.GLError: GLError(
	err = 1282,
	description = b'invalid operation',
	baseOperation = glUseProgram,
	cArguments = (6,)
)
[2025-10-04 01:47:48.580] {                 Renderable.py: 183} (              UIMain3DSub:   ERROR) - Unable to use the GL program because:
Traceback (most recent call last):
  File "/Users/dominiklang/Artemotion/scripts/engine3d/core/GLProgram.py", line 131, in use
    pygl.glUseProgram(self._id)
  File "/Users/dominiklang/Artemotion/venv/lib/python3.11/site-packages/OpenGL/error.py", line 230, in glCheckError
    raise self._errorClass(
OpenGL.error.GLError: GLError(
	err = 1282,
	description = b'invalid operation',
	baseOperation = glUseProgram,
	cArguments = (6,)
)
[2025-10-04 01:47:48.589] {                 Renderable.py: 183} (              UIMain3DSub:   ERROR) - Unable to use the GL program because:
Traceback (most recent call last):
  File "/Users/dominiklang/Artemotion/scripts/engine3d/core/GLProgram.py", line 131, in use
    pygl.glUseProgram(self._id)
  File "/Users/dominiklang/Artemotion/venv/lib/python3.11/site-packages/OpenGL/error.py", line 230, in glCheckError
    raise self._errorClass(
OpenGL.error.GLError: GLError(
	err = 1282,
	description = b'invalid operation',
	baseOperation = glUseProgram,
	cArguments = (6,)
)
[2025-10-04 01:47:48.594] {                 Renderable.py: 183} (              UIMain3DSub:   ERROR) - Unable to use the GL program because:
Traceback (most recent call last):
  File "/Users/dominiklang/Artemotion/scripts/engine3d/core/GLProgram.py", line 131, in use
    pygl.glUseProgram(self._id)
  File "/Users/dominiklang/Artemotion/venv/lib/python3.11/site-packages/OpenGL/error.py", line 230, in glCheckError
    raise self._errorClass(
OpenGL.error.GLError: GLError(
	err = 1282,
	description = b'invalid operation',
	baseOperation = glUseProgram,
	cArguments = (6,)
)
[2025-10-04 01:47:48.632] {                 Renderable.py: 183} (              UIMain3DSub:   ERROR) - Unable to use the GL program because:
Traceback (most recent call last):
  File "/Users/dominiklang/Artemotion/scripts/engine3d/core/GLProgram.py", line 131, in use
    pygl.glUseProgram(self._id)
  File "/Users/dominiklang/Artemotion/venv/lib/python3.11/site-packages/OpenGL/error.py", line 230, in glCheckError
    raise self._errorClass(
OpenGL.error.GLError: GLError(
	err = 1282,
	description = b'invalid operation',
	baseOperation = glUseProgram,
	cArguments = (6,)
)
[2025-10-04 01:47:48.639] {                 Renderable.py: 183} (              UIMain3DSub:   ERROR) - Unable to use the GL program because:
Traceback (most recent call last):
  File "/Users/dominiklang/Artemotion/scripts/engine3d/core/GLProgram.py", line 131, in use
    pygl.glUseProgram(self._id)
  File "/Users/dominiklang/Artemotion/venv/lib/python3.11/site-packages/OpenGL/error.py", line 230, in glCheckError
    raise self._errorClass(
OpenGL.error.GLError: GLError(
	err = 1282,
	description = b'invalid operation',
	baseOperation = glUseProgram,
	cArguments = (6,)
)
[2025-10-04 01:47:48.655] {                 Renderable.py: 183} (              UIMain3DSub:   ERROR) - Unable to use the GL program because:
Traceback (most recent call last):
  File "/Users/dominiklang/Artemotion/scripts/engine3d/core/GLProgram.py", line 131, in use
    pygl.glUseProgram(self._id)
  File "/Users/dominiklang/Artemotion/venv/lib/python3.11/site-packages/OpenGL/error.py", line 230, in glCheckError
    raise self._errorClass(
OpenGL.error.GLError: GLError(
	err = 1282,
	description = b'invalid operation',
	baseOperation = glUseProgram,
	cArguments = (6,)
)
[2025-10-04 01:47:48.672] {                 Renderable.py: 183} (              UIMain3DSub:   ERROR) - Unable to use the GL program because:
Traceback (most recent call last):
  File "/Users/dominiklang/Artemotion/scripts/engine3d/core/GLProgram.py", line 131, in use
    pygl.glUseProgram(self._id)
  File "/Users/dominiklang/Artemotion/venv/lib/python3.11/site-packages/OpenGL/error.py", line 230, in glCheckError
    raise self._errorClass(
OpenGL.error.GLError: GLError(
	err = 1282,
	description = b'invalid operation',
	baseOperation = glUseProgram,
	cArguments = (6,)
)
[2025-10-04 01:47:48.689] {                 Renderable.py: 183} (              UIMain3DSub:   ERROR) - Unable to use the GL program because:
Traceback (most recent call last):
  File "/Users/dominiklang/Artemotion/scripts/engine3d/core/GLProgram.py", line 131, in use
    pygl.glUseProgram(self._id)
  File "/Users/dominiklang/Artemotion/venv/lib/python3.11/site-packages/OpenGL/error.py", line 230, in glCheckError
    raise self._errorClass(
OpenGL.error.GLError: GLError(
	err = 1282,
	description = b'invalid operation',
	baseOperation = glUseProgram,
	cArguments = (6,)
)
[2025-10-04 01:47:48.706] {                 Renderable.py: 183} (              UIMain3DSub:   ERROR) - Unable to use the GL program because:
Traceback (most recent call last):
  File "/Users/dominiklang/Artemotion/scripts/engine3d/core/GLProgram.py", line 131, in use
    pygl.glUseProgram(self._id)
  File "/Users/dominiklang/Artemotion/venv/lib/python3.11/site-packages/OpenGL/error.py", line 230, in glCheckError
    raise self._errorClass(
OpenGL.error.GLError: GLError(
	err = 1282,
	description = b'invalid operation',
	baseOperation = glUseProgram,
	cArguments = (6,)
)
[2025-10-04 01:47:48.722] {                 Renderable.py: 183} (              UIMain3DSub:   ERROR) - Unable to use the GL program because:
Traceback (most recent call last):
  File "/Users/dominiklang/Artemotion/scripts/engine3d/core/GLProgram.py", line 131, in use
    pygl.glUseProgram(self._id)
  File "/Users/dominiklang/Artemotion/venv/lib/python3.11/site-packages/OpenGL/error.py", line 230, in glCheckError
    raise self._errorClass(
OpenGL.error.GLError: GLError(
	err = 1282,
	description = b'invalid operation',
	baseOperation = glUseProgram,
	cArguments = (6,)
)
[2025-10-04 01:47:48.739] {                 Renderable.py: 183} (              UIMain3DSub:   ERROR) - Unable to use the GL program because:
Traceback (most recent call last):
  File "/Users/dominiklang/Artemotion/scripts/engine3d/core/GLProgram.py", line 131, in use
    pygl.glUseProgram(self._id)
  File "/Users/dominiklang/Artemotion/venv/lib/python3.11/site-packages/OpenGL/error.py", line 230, in glCheckError
    raise self._errorClass(
OpenGL.error.GLError: GLError(
	err = 1282,
	description = b'invalid operation',
	baseOperation = glUseProgram,
	cArguments = (6,)
)
[2025-10-04 01:47:48.755] {                 Renderable.py: 183} (              UIMain3DSub:   ERROR) - Unable to use the GL program because:
Traceback (most recent call last):
  File "/Users/dominiklang/Artemotion/scripts/engine3d/core/GLProgram.py", line 131, in use
    pygl.glUseProgram(self._id)
  File "/Users/dominiklang/Artemotion/venv/lib/python3.11/site-packages/OpenGL/error.py", line 230, in glCheckError
    raise self._errorClass(
OpenGL.error.GLError: GLError(
	err = 1282,
	description = b'invalid operation',
	baseOperation = glUseProgram,
	cArguments = (6,)
)
[2025-10-04 01:47:48.772] {                 Renderable.py: 183} (              UIMain3DSub:   ERROR) - Unable to use the GL program because:
Traceback (most recent call last):
  File "/Users/dominiklang/Artemotion/scripts/engine3d/core/GLProgram.py", line 131, in use
    pygl.glUseProgram(self._id)
  File "/Users/dominiklang/Artemotion/venv/lib/python3.11/site-packages/OpenGL/error.py", line 230, in glCheckError
    raise self._errorClass(
OpenGL.error.GLError: GLError(
	err = 1282,
	description = b'invalid operation',
	baseOperation = glUseProgram,
	cArguments = (6,)
)
[2025-10-04 01:47:48.789] {                 Renderable.py: 183} (              UIMain3DSub:   ERROR) - Unable to use the GL program because:
Traceback (most recent call last):
  File "/Users/dominiklang/Artemotion/scripts/engine3d/core/GLProgram.py", line 131, in use
    pygl.glUseProgram(self._id)
  File "/Users/dominiklang/Artemotion/venv/lib/python3.11/site-packages/OpenGL/error.py", line 230, in glCheckError
    raise self._errorClass(
OpenGL.error.GLError: GLError(
	err = 1282,
	description = b'invalid operation',
	baseOperation = glUseProgram,
	cArguments = (6,)
)
[2025-10-04 01:47:48.805] {                 Renderable.py: 183} (              UIMain3DSub:   ERROR) - Unable to use the GL program because:
Traceback (most recent call last):
  File "/Users/dominiklang/Artemotion/scripts/engine3d/core/GLProgram.py", line 131, in use
    pygl.glUseProgram(self._id)
  File "/Users/dominiklang/Artemotion/venv/lib/python3.11/site-packages/OpenGL/error.py", line 230, in glCheckError
    raise self._errorClass(
OpenGL.error.GLError: GLError(
	err = 1282,
	description = b'invalid operation',
	baseOperation = glUseProgram,
	cArguments = (6,)
)
[2025-10-04 01:47:48.822] {                 Renderable.py: 183} (              UIMain3DSub:   ERROR) - Unable to use the GL program because:
Traceback (most recent call last):
  File "/Users/dominiklang/Artemotion/scripts/engine3d/core/GLProgram.py", line 131, in use
    pygl.glUseProgram(self._id)
  File "/Users/dominiklang/Artemotion/venv/lib/python3.11/site-packages/OpenGL/error.py", line 230, in glCheckError
    raise self._errorClass(
OpenGL.error.GLError: GLError(
	err = 1282,
	description = b'invalid operation',
	baseOperation = glUseProgram,
	cArguments = (6,)
)
[2025-10-04 01:47:48.839] {                 Renderable.py: 183} (              UIMain3DSub:   ERROR) - Unable to use the GL program because:
Traceback (most recent call last):
  File "/Users/dominiklang/Artemotion/scripts/engine3d/core/GLProgram.py", line 131, in use
    pygl.glUseProgram(self._id)
  File "/Users/dominiklang/Artemotion/venv/lib/python3.11/site-packages/OpenGL/error.py", line 230, in glCheckError
    raise self._errorClass(
OpenGL.error.GLError: GLError(
	err = 1282,
	description = b'invalid operation',
	baseOperation = glUseProgram,
	cArguments = (6,)
)
[2025-10-04 01:47:49.157] {                 Renderable.py: 183} (              UIMain3DSub:   ERROR) - Unable to use the GL program because:
Traceback (most recent call last):
  File "/Users/dominiklang/Artemotion/scripts/engine3d/core/GLProgram.py", line 131, in use
    pygl.glUseProgram(self._id)
  File "/Users/dominiklang/Artemotion/venv/lib/python3.11/site-packages/OpenGL/error.py", line 230, in glCheckError
    raise self._errorClass(
OpenGL.error.GLError: GLError(
	err = 1282,
	description = b'invalid operation',
	baseOperation = glUseProgram,
	cArguments = (6,)
)
[2025-10-04 01:47:49.163] {                 Renderable.py: 183} (              UIMain3DSub:   ERROR) - Unable to use the GL program because:
Traceback (most recent call last):
  File "/Users/dominiklang/Artemotion/scripts/engine3d/core/GLProgram.py", line 131, in use
    pygl.glUseProgram(self._id)
  File "/Users/dominiklang/Artemotion/venv/lib/python3.11/site-packages/OpenGL/error.py", line 230, in glCheckError
    raise self._errorClass(
OpenGL.error.GLError: GLError(
	err = 1282,
	description = b'invalid operation',
	baseOperation = glUseProgram,
	cArguments = (6,)
)
[2025-10-04 01:47:49.174] {                 Renderable.py: 183} (              UIMain3DSub:   ERROR) - Unable to use the GL program because:
Traceback (most recent call last):
  File "/Users/dominiklang/Artemotion/scripts/engine3d/core/GLProgram.py", line 131, in use
    pygl.glUseProgram(self._id)
  File "/Users/dominiklang/Artemotion/venv/lib/python3.11/site-packages/OpenGL/error.py", line 230, in glCheckError
    raise self._errorClass(
OpenGL.error.GLError: GLError(
	err = 1282,
	description = b'invalid operation',
	baseOperation = glUseProgram,
	cArguments = (6,)
)
[2025-10-04 01:47:49.197] {                 Renderable.py: 183} (              UIMain3DSub:   ERROR) - Unable to use the GL program because:
Traceback (most recent call last):
  File "/Users/dominiklang/Artemotion/scripts/engine3d/core/GLProgram.py", line 131, in use
    pygl.glUseProgram(self._id)
  File "/Users/dominiklang/Artemotion/venv/lib/python3.11/site-packages/OpenGL/error.py", line 230, in glCheckError
    raise self._errorClass(
OpenGL.error.GLError: GLError(
	err = 1282,
	description = b'invalid operation',
	baseOperation = glUseProgram,
	cArguments = (6,)
)
[2025-10-04 01:47:49.206] {                 Renderable.py: 183} (              UIMain3DSub:   ERROR) - Unable to use the GL program because:
Traceback (most recent call last):
  File "/Users/dominiklang/Artemotion/scripts/engine3d/core/GLProgram.py", line 131, in use
    pygl.glUseProgram(self._id)
  File "/Users/dominiklang/Artemotion/venv/lib/python3.11/site-packages/OpenGL/error.py", line 230, in glCheckError
    raise self._errorClass(
OpenGL.error.GLError: GLError(
	err = 1282,
	description = b'invalid operation',
	baseOperation = glUseProgram,
	cArguments = (6,)
)
[2025-10-04 01:47:49.213] {                 Renderable.py: 183} (              UIMain3DSub:   ERROR) - Unable to use the GL program because:
Traceback (most recent call last):
  File "/Users/dominiklang/Artemotion/scripts/engine3d/core/GLProgram.py", line 131, in use
    pygl.glUseProgram(self._id)
  File "/Users/dominiklang/Artemotion/venv/lib/python3.11/site-packages/OpenGL/error.py", line 230, in glCheckError
    raise self._errorClass(
OpenGL.error.GLError: GLError(
	err = 1282,
	description = b'invalid operation',
	baseOperation = glUseProgram,
	cArguments = (6,)
)
[2025-10-04 01:47:49.222] {                 Renderable.py: 183} (              UIMain3DSub:   ERROR) - Unable to use the GL program because:
Traceback (most recent call last):
  File "/Users/dominiklang/Artemotion/scripts/engine3d/core/GLProgram.py", line 131, in use
    pygl.glUseProgram(self._id)
  File "/Users/dominiklang/Artemotion/venv/lib/python3.11/site-packages/OpenGL/error.py", line 230, in glCheckError
    raise self._errorClass(
OpenGL.error.GLError: GLError(
	err = 1282,
	description = b'invalid operation',
	baseOperation = glUseProgram,
	cArguments = (6,)
)
[2025-10-04 01:47:49.226] {                 Renderable.py: 183} (              UIMain3DSub:   ERROR) - Unable to use the GL program because:
Traceback (most recent call last):
  File "/Users/dominiklang/Artemotion/scripts/engine3d/core/GLProgram.py", line 131, in use
    pygl.glUseProgram(self._id)
  File "/Users/dominiklang/Artemotion/venv/lib/python3.11/site-packages/OpenGL/error.py", line 230, in glCheckError
    raise self._errorClass(
OpenGL.error.GLError: GLError(
	err = 1282,
	description = b'invalid operation',
	baseOperation = glUseProgram,
	cArguments = (6,)
)
[2025-10-04 01:47:49.239] {                 Renderable.py: 183} (              UIMain3DSub:   ERROR) - Unable to use the GL program because:
Traceback (most recent call last):
  File "/Users/dominiklang/Artemotion/scripts/engine3d/core/GLProgram.py", line 131, in use
    pygl.glUseProgram(self._id)
  File "/Users/dominiklang/Artemotion/venv/lib/python3.11/site-packages/OpenGL/error.py", line 230, in glCheckError
    raise self._errorClass(
OpenGL.error.GLError: GLError(
	err = 1282,
	description = b'invalid operation',
	baseOperation = glUseProgram,
	cArguments = (6,)
)
[2025-10-04 01:47:49.255] {                 Renderable.py: 183} (              UIMain3DSub:   ERROR) - Unable to use the GL program because:
Traceback (most recent call last):
  File "/Users/dominiklang/Artemotion/scripts/engine3d/core/GLProgram.py", line 131, in use
    pygl.glUseProgram(self._id)
  File "/Users/dominiklang/Artemotion/venv/lib/python3.11/site-packages/OpenGL/error.py", line 230, in glCheckError
    raise self._errorClass(
OpenGL.error.GLError: GLError(
	err = 1282,
	description = b'invalid operation',
	baseOperation = glUseProgram,
	cArguments = (6,)
)
[2025-10-04 01:47:49.272] {                 Renderable.py: 183} (              UIMain3DSub:   ERROR) - Unable to use the GL program because:
Traceback (most recent call last):
  File "/Users/dominiklang/Artemotion/scripts/engine3d/core/GLProgram.py", line 131, in use
    pygl.glUseProgram(self._id)
  File "/Users/dominiklang/Artemotion/venv/lib/python3.11/site-packages/OpenGL/error.py", line 230, in glCheckError
    raise self._errorClass(
OpenGL.error.GLError: GLError(
	err = 1282,
	description = b'invalid operation',
	baseOperation = glUseProgram,
	cArguments = (6,)
)
[2025-10-04 01:47:49.289] {                 Renderable.py: 183} (              UIMain3DSub:   ERROR) - Unable to use the GL program because:
Traceback (most recent call last):
  File "/Users/dominiklang/Artemotion/scripts/engine3d/core/GLProgram.py", line 131, in use
    pygl.glUseProgram(self._id)
  File "/Users/dominiklang/Artemotion/venv/lib/python3.11/site-packages/OpenGL/error.py", line 230, in glCheckError
    raise self._errorClass(
OpenGL.error.GLError: GLError(
	err = 1282,
	description = b'invalid operation',
	baseOperation = glUseProgram,
	cArguments = (6,)
)
[2025-10-04 01:47:49.305] {                 Renderable.py: 183} (              UIMain3DSub:   ERROR) - Unable to use the GL program because:
Traceback (most recent call last):
  File "/Users/dominiklang/Artemotion/scripts/engine3d/core/GLProgram.py", line 131, in use
    pygl.glUseProgram(self._id)
  File "/Users/dominiklang/Artemotion/venv/lib/python3.11/site-packages/OpenGL/error.py", line 230, in glCheckError
    raise self._errorClass(
OpenGL.error.GLError: GLError(
	err = 1282,
	description = b'invalid operation',
	baseOperation = glUseProgram,
	cArguments = (6,)
)
[2025-10-04 01:47:49.323] {                 Renderable.py: 183} (              UIMain3DSub:   ERROR) - Unable to use the GL program because:
Traceback (most recent call last):
  File "/Users/dominiklang/Artemotion/scripts/engine3d/core/GLProgram.py", line 131, in use
    pygl.glUseProgram(self._id)
  File "/Users/dominiklang/Artemotion/venv/lib/python3.11/site-packages/OpenGL/error.py", line 230, in glCheckError
    raise self._errorClass(
OpenGL.error.GLError: GLError(
	err = 1282,
	description = b'invalid operation',
	baseOperation = glUseProgram,
	cArguments = (6,)
)
[2025-10-04 01:47:49.555] {                 Renderable.py: 183} (              UIMain3DSub:   ERROR) - Unable to use the GL program because:
Traceback (most recent call last):
  File "/Users/dominiklang/Artemotion/scripts/engine3d/core/GLProgram.py", line 131, in use
    pygl.glUseProgram(self._id)
  File "/Users/dominiklang/Artemotion/venv/lib/python3.11/site-packages/OpenGL/error.py", line 230, in glCheckError
    raise self._errorClass(
OpenGL.error.GLError: GLError(
	err = 1282,
	description = b'invalid operation',
	baseOperation = glUseProgram,
	cArguments = (6,)
)
[2025-10-04 01:47:49.560] {                 Renderable.py: 183} (              UIMain3DSub:   ERROR) - Unable to use the GL program because:
Traceback (most recent call last):
  File "/Users/dominiklang/Artemotion/scripts/engine3d/core/GLProgram.py", line 131, in use
    pygl.glUseProgram(self._id)
  File "/Users/dominiklang/Artemotion/venv/lib/python3.11/site-packages/OpenGL/error.py", line 230, in glCheckError
    raise self._errorClass(
OpenGL.error.GLError: GLError(
	err = 1282,
	description = b'invalid operation',
	baseOperation = glUseProgram,
	cArguments = (6,)
)
[2025-10-04 01:47:49.589] {                 Renderable.py: 183} (              UIMain3DSub:   ERROR) - Unable to use the GL program because:
Traceback (most recent call last):
  File "/Users/dominiklang/Artemotion/scripts/engine3d/core/GLProgram.py", line 131, in use
    pygl.glUseProgram(self._id)
  File "/Users/dominiklang/Artemotion/venv/lib/python3.11/site-packages/OpenGL/error.py", line 230, in glCheckError
    raise self._errorClass(
OpenGL.error.GLError: GLError(
	err = 1282,
	description = b'invalid operation',
	baseOperation = glUseProgram,
	cArguments = (6,)
)
[2025-10-04 01:47:49.593] {                 Renderable.py: 183} (              UIMain3DSub:   ERROR) - Unable to use the GL program because:
Traceback (most recent call last):
  File "/Users/dominiklang/Artemotion/scripts/engine3d/core/GLProgram.py", line 131, in use
    pygl.glUseProgram(self._id)
  File "/Users/dominiklang/Artemotion/venv/lib/python3.11/site-packages/OpenGL/error.py", line 230, in glCheckError
    raise self._errorClass(
OpenGL.error.GLError: GLError(
	err = 1282,
	description = b'invalid operation',
	baseOperation = glUseProgram,
	cArguments = (6,)
)
[2025-10-04 01:47:51.507] {                 Renderable.py: 183} (              UIMain3DSub:   ERROR) - Unable to use the GL program because:
Traceback (most recent call last):
  File "/Users/dominiklang/Artemotion/scripts/engine3d/core/GLProgram.py", line 131, in use
    pygl.glUseProgram(self._id)
  File "/Users/dominiklang/Artemotion/venv/lib/python3.11/site-packages/OpenGL/error.py", line 230, in glCheckError
    raise self._errorClass(
OpenGL.error.GLError: GLError(
	err = 1282,
	description = b'invalid operation',
	baseOperation = glUseProgram,
	cArguments = (6,)
)
[2025-10-04 01:47:51.536] {                 Renderable.py: 183} (              UIMain3DSub:   ERROR) - Unable to use the GL program because:
Traceback (most recent call last):
  File "/Users/dominiklang/Artemotion/scripts/engine3d/core/GLProgram.py", line 131, in use
    pygl.glUseProgram(self._id)
  File "/Users/dominiklang/Artemotion/venv/lib/python3.11/site-packages/OpenGL/error.py", line 230, in glCheckError
    raise self._errorClass(
OpenGL.error.GLError: GLError(
	err = 1282,
	description = b'invalid operation',
	baseOperation = glUseProgram,
	cArguments = (6,)
)
[2025-10-04 01:47:51.550] {                 Renderable.py: 183} (              UIMain3DSub:   ERROR) - Unable to use the GL program because:
Traceback (most recent call last):
  File "/Users/dominiklang/Artemotion/scripts/engine3d/core/GLProgram.py", line 131, in use
    pygl.glUseProgram(self._id)
  File "/Users/dominiklang/Artemotion/venv/lib/python3.11/site-packages/OpenGL/error.py", line 230, in glCheckError
    raise self._errorClass(
OpenGL.error.GLError: GLError(
	err = 1282,
	description = b'invalid operation',
	baseOperation = glUseProgram,
	cArguments = (6,)
)
[2025-10-04 01:47:51.555] {                 Renderable.py: 183} (              UIMain3DSub:   ERROR) - Unable to use the GL program because:
Traceback (most recent call last):
  File "/Users/dominiklang/Artemotion/scripts/engine3d/core/GLProgram.py", line 131, in use
    pygl.glUseProgram(self._id)
  File "/Users/dominiklang/Artemotion/venv/lib/python3.11/site-packages/OpenGL/error.py", line 230, in glCheckError
    raise self._errorClass(
OpenGL.error.GLError: GLError(
	err = 1282,
	description = b'invalid operation',
	baseOperation = glUseProgram,
	cArguments = (6,)
)
[2025-10-04 01:47:51.585] {                 Renderable.py: 183} (              UIMain3DSub:   ERROR) - Unable to use the GL program because:
Traceback (most recent call last):
  File "/Users/dominiklang/Artemotion/scripts/engine3d/core/GLProgram.py", line 131, in use
    pygl.glUseProgram(self._id)
  File "/Users/dominiklang/Artemotion/venv/lib/python3.11/site-packages/OpenGL/error.py", line 230, in glCheckError
    raise self._errorClass(
OpenGL.error.GLError: GLError(
	err = 1282,
	description = b'invalid operation',
	baseOperation = glUseProgram,
	cArguments = (6,)
)
[2025-10-04 01:47:51.591] {                 Renderable.py: 183} (              UIMain3DSub:   ERROR) - Unable to use the GL program because:
Traceback (most recent call last):
  File "/Users/dominiklang/Artemotion/scripts/engine3d/core/GLProgram.py", line 131, in use
    pygl.glUseProgram(self._id)
  File "/Users/dominiklang/Artemotion/venv/lib/python3.11/site-packages/OpenGL/error.py", line 230, in glCheckError
    raise self._errorClass(
OpenGL.error.GLError: GLError(
	err = 1282,
	description = b'invalid operation',
	baseOperation = glUseProgram,
	cArguments = (6,)
)
[2025-10-04 01:47:51.593] {                 Renderable.py: 183} (              UIMain3DSub:   ERROR) - Unable to use the GL program because:
Traceback (most recent call last):
  File "/Users/dominiklang/Artemotion/scripts/engine3d/core/GLProgram.py", line 131, in use
    pygl.glUseProgram(self._id)
  File "/Users/dominiklang/Artemotion/venv/lib/python3.11/site-packages/OpenGL/error.py", line 230, in glCheckError
    raise self._errorClass(
OpenGL.error.GLError: GLError(
	err = 1282,
	description = b'invalid operation',
	baseOperation = glUseProgram,
	cArguments = (6,)
)
[2025-10-04 01:47:51.605] {                 Renderable.py: 183} (              UIMain3DSub:   ERROR) - Unable to use the GL program because:
Traceback (most recent call last):
  File "/Users/dominiklang/Artemotion/scripts/engine3d/core/GLProgram.py", line 131, in use
    pygl.glUseProgram(self._id)
  File "/Users/dominiklang/Artemotion/venv/lib/python3.11/site-packages/OpenGL/error.py", line 230, in glCheckError
    raise self._errorClass(
OpenGL.error.GLError: GLError(
	err = 1282,
	description = b'invalid operation',
	baseOperation = glUseProgram,
	cArguments = (6,)
)
[2025-10-04 01:47:51.611] {                 Renderable.py: 183} (              UIMain3DSub:   ERROR) - Unable to use the GL program because:
Traceback (most recent call last):
  File "/Users/dominiklang/Artemotion/scripts/engine3d/core/GLProgram.py", line 131, in use
    pygl.glUseProgram(self._id)
  File "/Users/dominiklang/Artemotion/venv/lib/python3.11/site-packages/OpenGL/error.py", line 230, in glCheckError
    raise self._errorClass(
OpenGL.error.GLError: GLError(
	err = 1282,
	description = b'invalid operation',
	baseOperation = glUseProgram,
	cArguments = (6,)
)
[2025-10-04 01:47:51.622] {                 Renderable.py: 183} (              UIMain3DSub:   ERROR) - Unable to use the GL program because:
Traceback (most recent call last):
  File "/Users/dominiklang/Artemotion/scripts/engine3d/core/GLProgram.py", line 131, in use
    pygl.glUseProgram(self._id)
  File "/Users/dominiklang/Artemotion/venv/lib/python3.11/site-packages/OpenGL/error.py", line 230, in glCheckError
    raise self._errorClass(
OpenGL.error.GLError: GLError(
	err = 1282,
	description = b'invalid operation',
	baseOperation = glUseProgram,
	cArguments = (6,)
)
[2025-10-04 01:47:51.626] {                 Renderable.py: 183} (              UIMain3DSub:   ERROR) - Unable to use the GL program because:
Traceback (most recent call last):
  File "/Users/dominiklang/Artemotion/scripts/engine3d/core/GLProgram.py", line 131, in use
    pygl.glUseProgram(self._id)
  File "/Users/dominiklang/Artemotion/venv/lib/python3.11/site-packages/OpenGL/error.py", line 230, in glCheckError
    raise self._errorClass(
OpenGL.error.GLError: GLError(
	err = 1282,
	description = b'invalid operation',
	baseOperation = glUseProgram,
	cArguments = (6,)
)
[2025-10-04 01:47:51.639] {                 Renderable.py: 183} (              UIMain3DSub:   ERROR) - Unable to use the GL program because:
Traceback (most recent call last):
  File "/Users/dominiklang/Artemotion/scripts/engine3d/core/GLProgram.py", line 131, in use
    pygl.glUseProgram(self._id)
  File "/Users/dominiklang/Artemotion/venv/lib/python3.11/site-packages/OpenGL/error.py", line 230, in glCheckError
    raise self._errorClass(
OpenGL.error.GLError: GLError(
	err = 1282,
	description = b'invalid operation',
	baseOperation = glUseProgram,
	cArguments = (6,)
)
[2025-10-04 01:47:51.655] {                 Renderable.py: 183} (              UIMain3DSub:   ERROR) - Unable to use the GL program because:
Traceback (most recent call last):
  File "/Users/dominiklang/Artemotion/scripts/engine3d/core/GLProgram.py", line 131, in use
    pygl.glUseProgram(self._id)
  File "/Users/dominiklang/Artemotion/venv/lib/python3.11/site-packages/OpenGL/error.py", line 230, in glCheckError
    raise self._errorClass(
OpenGL.error.GLError: GLError(
	err = 1282,
	description = b'invalid operation',
	baseOperation = glUseProgram,
	cArguments = (6,)
)
[2025-10-04 01:47:51.672] {                 Renderable.py: 183} (              UIMain3DSub:   ERROR) - Unable to use the GL program because:
Traceback (most recent call last):
  File "/Users/dominiklang/Artemotion/scripts/engine3d/core/GLProgram.py", line 131, in use
    pygl.glUseProgram(self._id)
  File "/Users/dominiklang/Artemotion/venv/lib/python3.11/site-packages/OpenGL/error.py", line 230, in glCheckError
    raise self._errorClass(
OpenGL.error.GLError: GLError(
	err = 1282,
	description = b'invalid operation',
	baseOperation = glUseProgram,
	cArguments = (6,)
)
[2025-10-04 01:47:51.689] {                 Renderable.py: 183} (              UIMain3DSub:   ERROR) - Unable to use the GL program because:
Traceback (most recent call last):
  File "/Users/dominiklang/Artemotion/scripts/engine3d/core/GLProgram.py", line 131, in use
    pygl.glUseProgram(self._id)
  File "/Users/dominiklang/Artemotion/venv/lib/python3.11/site-packages/OpenGL/error.py", line 230, in glCheckError
    raise self._errorClass(
OpenGL.error.GLError: GLError(
	err = 1282,
	description = b'invalid operation',
	baseOperation = glUseProgram,
	cArguments = (6,)
)
[2025-10-04 01:47:51.723] {                 Renderable.py: 183} (              UIMain3DSub:   ERROR) - Unable to use the GL program because:
Traceback (most recent call last):
  File "/Users/dominiklang/Artemotion/scripts/engine3d/core/GLProgram.py", line 131, in use
    pygl.glUseProgram(self._id)
  File "/Users/dominiklang/Artemotion/venv/lib/python3.11/site-packages/OpenGL/error.py", line 230, in glCheckError
    raise self._errorClass(
OpenGL.error.GLError: GLError(
	err = 1282,
	description = b'invalid operation',
	baseOperation = glUseProgram,
	cArguments = (6,)
)
[2025-10-04 01:47:51.739] {                 Renderable.py: 183} (              UIMain3DSub:   ERROR) - Unable to use the GL program because:
Traceback (most recent call last):
  File "/Users/dominiklang/Artemotion/scripts/engine3d/core/GLProgram.py", line 131, in use
    pygl.glUseProgram(self._id)
  File "/Users/dominiklang/Artemotion/venv/lib/python3.11/site-packages/OpenGL/error.py", line 230, in glCheckError
    raise self._errorClass(
OpenGL.error.GLError: GLError(
	err = 1282,
	description = b'invalid operation',
	baseOperation = glUseProgram,
	cArguments = (6,)
)
[2025-10-04 01:47:51.755] {                 Renderable.py: 183} (              UIMain3DSub:   ERROR) - Unable to use the GL program because:
Traceback (most recent call last):
  File "/Users/dominiklang/Artemotion/scripts/engine3d/core/GLProgram.py", line 131, in use
    pygl.glUseProgram(self._id)
  File "/Users/dominiklang/Artemotion/venv/lib/python3.11/site-packages/OpenGL/error.py", line 230, in glCheckError
    raise self._errorClass(
OpenGL.error.GLError: GLError(
	err = 1282,
	description = b'invalid operation',
	baseOperation = glUseProgram,
	cArguments = (6,)
)
[2025-10-04 01:47:51.785] {                 Renderable.py: 183} (              UIMain3DSub:   ERROR) - Unable to use the GL program because:
Traceback (most recent call last):
  File "/Users/dominiklang/Artemotion/scripts/engine3d/core/GLProgram.py", line 131, in use
    pygl.glUseProgram(self._id)
  File "/Users/dominiklang/Artemotion/venv/lib/python3.11/site-packages/OpenGL/error.py", line 230, in glCheckError
    raise self._errorClass(
OpenGL.error.GLError: GLError(
	err = 1282,
	description = b'invalid operation',
	baseOperation = glUseProgram,
	cArguments = (6,)
)
[2025-10-04 01:47:51.789] {                 Renderable.py: 183} (              UIMain3DSub:   ERROR) - Unable to use the GL program because:
Traceback (most recent call last):
  File "/Users/dominiklang/Artemotion/scripts/engine3d/core/GLProgram.py", line 131, in use
    pygl.glUseProgram(self._id)
  File "/Users/dominiklang/Artemotion/venv/lib/python3.11/site-packages/OpenGL/error.py", line 230, in glCheckError
    raise self._errorClass(
OpenGL.error.GLError: GLError(
	err = 1282,
	description = b'invalid operation',
	baseOperation = glUseProgram,
	cArguments = (6,)
)
[2025-10-04 01:47:51.805] {                 Renderable.py: 183} (              UIMain3DSub:   ERROR) - Unable to use the GL program because:
Traceback (most recent call last):
  File "/Users/dominiklang/Artemotion/scripts/engine3d/core/GLProgram.py", line 131, in use
    pygl.glUseProgram(self._id)
  File "/Users/dominiklang/Artemotion/venv/lib/python3.11/site-packages/OpenGL/error.py", line 230, in glCheckError
    raise self._errorClass(
OpenGL.error.GLError: GLError(
	err = 1282,
	description = b'invalid operation',
	baseOperation = glUseProgram,
	cArguments = (6,)
)
[2025-10-04 01:47:51.811] {                 Renderable.py: 183} (              UIMain3DSub:   ERROR) - Unable to use the GL program because:
Traceback (most recent call last):
  File "/Users/dominiklang/Artemotion/scripts/engine3d/core/GLProgram.py", line 131, in use
    pygl.glUseProgram(self._id)
  File "/Users/dominiklang/Artemotion/venv/lib/python3.11/site-packages/OpenGL/error.py", line 230, in glCheckError
    raise self._errorClass(
OpenGL.error.GLError: GLError(
	err = 1282,
	description = b'invalid operation',
	baseOperation = glUseProgram,
	cArguments = (6,)
)
[2025-10-04 01:47:51.822] {                 Renderable.py: 183} (              UIMain3DSub:   ERROR) - Unable to use the GL program because:
Traceback (most recent call last):
  File "/Users/dominiklang/Artemotion/scripts/engine3d/core/GLProgram.py", line 131, in use
    pygl.glUseProgram(self._id)
  File "/Users/dominiklang/Artemotion/venv/lib/python3.11/site-packages/OpenGL/error.py", line 230, in glCheckError
    raise self._errorClass(
OpenGL.error.GLError: GLError(
	err = 1282,
	description = b'invalid operation',
	baseOperation = glUseProgram,
	cArguments = (6,)
)
[2025-10-04 01:47:51.829] {                 Renderable.py: 183} (              UIMain3DSub:   ERROR) - Unable to use the GL program because:
Traceback (most recent call last):
  File "/Users/dominiklang/Artemotion/scripts/engine3d/core/GLProgram.py", line 131, in use
    pygl.glUseProgram(self._id)
  File "/Users/dominiklang/Artemotion/venv/lib/python3.11/site-packages/OpenGL/error.py", line 230, in glCheckError
    raise self._errorClass(
OpenGL.error.GLError: GLError(
	err = 1282,
	description = b'invalid operation',
	baseOperation = glUseProgram,
	cArguments = (6,)
)
[2025-10-04 01:47:51.838] {                 Renderable.py: 183} (              UIMain3DSub:   ERROR) - Unable to use the GL program because:
Traceback (most recent call last):
  File "/Users/dominiklang/Artemotion/scripts/engine3d/core/GLProgram.py", line 131, in use
    pygl.glUseProgram(self._id)
  File "/Users/dominiklang/Artemotion/venv/lib/python3.11/site-packages/OpenGL/error.py", line 230, in glCheckError
    raise self._errorClass(
OpenGL.error.GLError: GLError(
	err = 1282,
	description = b'invalid operation',
	baseOperation = glUseProgram,
	cArguments = (6,)
)
[2025-10-04 01:47:51.843] {                 Renderable.py: 183} (              UIMain3DSub:   ERROR) - Unable to use the GL program because:
Traceback (most recent call last):
  File "/Users/dominiklang/Artemotion/scripts/engine3d/core/GLProgram.py", line 131, in use
    pygl.glUseProgram(self._id)
  File "/Users/dominiklang/Artemotion/venv/lib/python3.11/site-packages/OpenGL/error.py", line 230, in glCheckError
    raise self._errorClass(
OpenGL.error.GLError: GLError(
	err = 1282,
	description = b'invalid operation',
	baseOperation = glUseProgram,
	cArguments = (6,)
)
[2025-10-04 01:47:51.855] {                 Renderable.py: 183} (              UIMain3DSub:   ERROR) - Unable to use the GL program because:
Traceback (most recent call last):
  File "/Users/dominiklang/Artemotion/scripts/engine3d/core/GLProgram.py", line 131, in use
    pygl.glUseProgram(self._id)
  File "/Users/dominiklang/Artemotion/venv/lib/python3.11/site-packages/OpenGL/error.py", line 230, in glCheckError
    raise self._errorClass(
OpenGL.error.GLError: GLError(
	err = 1282,
	description = b'invalid operation',
	baseOperation = glUseProgram,
	cArguments = (6,)
)
[2025-10-04 01:47:51.874] {                 Renderable.py: 183} (              UIMain3DSub:   ERROR) - Unable to use the GL program because:
Traceback (most recent call last):
  File "/Users/dominiklang/Artemotion/scripts/engine3d/core/GLProgram.py", line 131, in use
    pygl.glUseProgram(self._id)
  File "/Users/dominiklang/Artemotion/venv/lib/python3.11/site-packages/OpenGL/error.py", line 230, in glCheckError
    raise self._errorClass(
OpenGL.error.GLError: GLError(
	err = 1282,
	description = b'invalid operation',
	baseOperation = glUseProgram,
	cArguments = (6,)
)
[2025-10-04 01:47:51.881] {                 Renderable.py: 183} (              UIMain3DSub:   ERROR) - Unable to use the GL program because:
Traceback (most recent call last):
  File "/Users/dominiklang/Artemotion/scripts/engine3d/core/GLProgram.py", line 131, in use
    pygl.glUseProgram(self._id)
  File "/Users/dominiklang/Artemotion/venv/lib/python3.11/site-packages/OpenGL/error.py", line 230, in glCheckError
    raise self._errorClass(
OpenGL.error.GLError: GLError(
	err = 1282,
	description = b'invalid operation',
	baseOperation = glUseProgram,
	cArguments = (6,)
)
[2025-10-04 01:47:51.889] {                 Renderable.py: 183} (              UIMain3DSub:   ERROR) - Unable to use the GL program because:
Traceback (most recent call last):
  File "/Users/dominiklang/Artemotion/scripts/engine3d/core/GLProgram.py", line 131, in use
    pygl.glUseProgram(self._id)
  File "/Users/dominiklang/Artemotion/venv/lib/python3.11/site-packages/OpenGL/error.py", line 230, in glCheckError
    raise self._errorClass(
OpenGL.error.GLError: GLError(
	err = 1282,
	description = b'invalid operation',
	baseOperation = glUseProgram,
	cArguments = (6,)
)
[2025-10-04 01:47:51.897] {                 Renderable.py: 183} (              UIMain3DSub:   ERROR) - Unable to use the GL program because:
Traceback (most recent call last):
  File "/Users/dominiklang/Artemotion/scripts/engine3d/core/GLProgram.py", line 131, in use
    pygl.glUseProgram(self._id)
  File "/Users/dominiklang/Artemotion/venv/lib/python3.11/site-packages/OpenGL/error.py", line 230, in glCheckError
    raise self._errorClass(
OpenGL.error.GLError: GLError(
	err = 1282,
	description = b'invalid operation',
	baseOperation = glUseProgram,
	cArguments = (6,)
)
[2025-10-04 01:47:51.922] {                 Renderable.py: 183} (              UIMain3DSub:   ERROR) - Unable to use the GL program because:
Traceback (most recent call last):
  File "/Users/dominiklang/Artemotion/scripts/engine3d/core/GLProgram.py", line 131, in use
    pygl.glUseProgram(self._id)
  File "/Users/dominiklang/Artemotion/venv/lib/python3.11/site-packages/OpenGL/error.py", line 230, in glCheckError
    raise self._errorClass(
OpenGL.error.GLError: GLError(
	err = 1282,
	description = b'invalid operation',
	baseOperation = glUseProgram,
	cArguments = (6,)
)
[2025-10-04 01:47:52.072] {                 Renderable.py: 183} (              UIMain3DSub:   ERROR) - Unable to use the GL program because:
Traceback (most recent call last):
  File "/Users/dominiklang/Artemotion/scripts/engine3d/core/GLProgram.py", line 131, in use
    pygl.glUseProgram(self._id)
  File "/Users/dominiklang/Artemotion/venv/lib/python3.11/site-packages/OpenGL/error.py", line 230, in glCheckError
    raise self._errorClass(
OpenGL.error.GLError: GLError(
	err = 1282,
	description = b'invalid operation',
	baseOperation = glUseProgram,
	cArguments = (6,)
)
[2025-10-04 01:47:52.089] {                 Renderable.py: 183} (              UIMain3DSub:   ERROR) - Unable to use the GL program because:
Traceback (most recent call last):
  File "/Users/dominiklang/Artemotion/scripts/engine3d/core/GLProgram.py", line 131, in use
    pygl.glUseProgram(self._id)
  File "/Users/dominiklang/Artemotion/venv/lib/python3.11/site-packages/OpenGL/error.py", line 230, in glCheckError
    raise self._errorClass(
OpenGL.error.GLError: GLError(
	err = 1282,
	description = b'invalid operation',
	baseOperation = glUseProgram,
	cArguments = (6,)
)
[2025-10-04 01:47:52.095] {                 Renderable.py: 183} (              UIMain3DSub:   ERROR) - Unable to use the GL program because:
Traceback (most recent call last):
  File "/Users/dominiklang/Artemotion/scripts/engine3d/core/GLProgram.py", line 131, in use
    pygl.glUseProgram(self._id)
  File "/Users/dominiklang/Artemotion/venv/lib/python3.11/site-packages/OpenGL/error.py", line 230, in glCheckError
    raise self._errorClass(
OpenGL.error.GLError: GLError(
	err = 1282,
	description = b'invalid operation',
	baseOperation = glUseProgram,
	cArguments = (6,)
)
[2025-10-04 01:47:52.105] {                 Renderable.py: 183} (              UIMain3DSub:   ERROR) - Unable to use the GL program because:
Traceback (most recent call last):
  File "/Users/dominiklang/Artemotion/scripts/engine3d/core/GLProgram.py", line 131, in use
    pygl.glUseProgram(self._id)
  File "/Users/dominiklang/Artemotion/venv/lib/python3.11/site-packages/OpenGL/error.py", line 230, in glCheckError
    raise self._errorClass(
OpenGL.error.GLError: GLError(
	err = 1282,
	description = b'invalid operation',
	baseOperation = glUseProgram,
	cArguments = (6,)
)
[2025-10-04 01:47:52.109] {                 Renderable.py: 183} (              UIMain3DSub:   ERROR) - Unable to use the GL program because:
Traceback (most recent call last):
  File "/Users/dominiklang/Artemotion/scripts/engine3d/core/GLProgram.py", line 131, in use
    pygl.glUseProgram(self._id)
  File "/Users/dominiklang/Artemotion/venv/lib/python3.11/site-packages/OpenGL/error.py", line 230, in glCheckError
    raise self._errorClass(
OpenGL.error.GLError: GLError(
	err = 1282,
	description = b'invalid operation',
	baseOperation = glUseProgram,
	cArguments = (6,)
)
[2025-10-04 01:47:52.122] {                 Renderable.py: 183} (              UIMain3DSub:   ERROR) - Unable to use the GL program because:
Traceback (most recent call last):
  File "/Users/dominiklang/Artemotion/scripts/engine3d/core/GLProgram.py", line 131, in use
    pygl.glUseProgram(self._id)
  File "/Users/dominiklang/Artemotion/venv/lib/python3.11/site-packages/OpenGL/error.py", line 230, in glCheckError
    raise self._errorClass(
OpenGL.error.GLError: GLError(
	err = 1282,
	description = b'invalid operation',
	baseOperation = glUseProgram,
	cArguments = (6,)
)
[2025-10-04 01:47:52.128] {                 Renderable.py: 183} (              UIMain3DSub:   ERROR) - Unable to use the GL program because:
Traceback (most recent call last):
  File "/Users/dominiklang/Artemotion/scripts/engine3d/core/GLProgram.py", line 131, in use
    pygl.glUseProgram(self._id)
  File "/Users/dominiklang/Artemotion/venv/lib/python3.11/site-packages/OpenGL/error.py", line 230, in glCheckError
    raise self._errorClass(
OpenGL.error.GLError: GLError(
	err = 1282,
	description = b'invalid operation',
	baseOperation = glUseProgram,
	cArguments = (6,)
)
[2025-10-04 01:47:52.138] {                 Renderable.py: 183} (              UIMain3DSub:   ERROR) - Unable to use the GL program because:
Traceback (most recent call last):
  File "/Users/dominiklang/Artemotion/scripts/engine3d/core/GLProgram.py", line 131, in use
    pygl.glUseProgram(self._id)
  File "/Users/dominiklang/Artemotion/venv/lib/python3.11/site-packages/OpenGL/error.py", line 230, in glCheckError
    raise self._errorClass(
OpenGL.error.GLError: GLError(
	err = 1282,
	description = b'invalid operation',
	baseOperation = glUseProgram,
	cArguments = (6,)
)
[2025-10-04 01:47:52.146] {                 Renderable.py: 183} (              UIMain3DSub:   ERROR) - Unable to use the GL program because:
Traceback (most recent call last):
  File "/Users/dominiklang/Artemotion/scripts/engine3d/core/GLProgram.py", line 131, in use
    pygl.glUseProgram(self._id)
  File "/Users/dominiklang/Artemotion/venv/lib/python3.11/site-packages/OpenGL/error.py", line 230, in glCheckError
    raise self._errorClass(
OpenGL.error.GLError: GLError(
	err = 1282,
	description = b'invalid operation',
	baseOperation = glUseProgram,
	cArguments = (6,)
)
[2025-10-04 01:47:52.155] {                 Renderable.py: 183} (              UIMain3DSub:   ERROR) - Unable to use the GL program because:
Traceback (most recent call last):
  File "/Users/dominiklang/Artemotion/scripts/engine3d/core/GLProgram.py", line 131, in use
    pygl.glUseProgram(self._id)
  File "/Users/dominiklang/Artemotion/venv/lib/python3.11/site-packages/OpenGL/error.py", line 230, in glCheckError
    raise self._errorClass(
OpenGL.error.GLError: GLError(
	err = 1282,
	description = b'invalid operation',
	baseOperation = glUseProgram,
	cArguments = (6,)
)
[2025-10-04 01:47:52.161] {                 Renderable.py: 183} (              UIMain3DSub:   ERROR) - Unable to use the GL program because:
Traceback (most recent call last):
  File "/Users/dominiklang/Artemotion/scripts/engine3d/core/GLProgram.py", line 131, in use
    pygl.glUseProgram(self._id)
  File "/Users/dominiklang/Artemotion/venv/lib/python3.11/site-packages/OpenGL/error.py", line 230, in glCheckError
    raise self._errorClass(
OpenGL.error.GLError: GLError(
	err = 1282,
	description = b'invalid operation',
	baseOperation = glUseProgram,
	cArguments = (6,)
)
[2025-10-04 01:47:52.172] {                 Renderable.py: 183} (              UIMain3DSub:   ERROR) - Unable to use the GL program because:
Traceback (most recent call last):
  File "/Users/dominiklang/Artemotion/scripts/engine3d/core/GLProgram.py", line 131, in use
    pygl.glUseProgram(self._id)
  File "/Users/dominiklang/Artemotion/venv/lib/python3.11/site-packages/OpenGL/error.py", line 230, in glCheckError
    raise self._errorClass(
OpenGL.error.GLError: GLError(
	err = 1282,
	description = b'invalid operation',
	baseOperation = glUseProgram,
	cArguments = (6,)
)
[2025-10-04 01:47:52.176] {                 Renderable.py: 183} (              UIMain3DSub:   ERROR) - Unable to use the GL program because:
Traceback (most recent call last):
  File "/Users/dominiklang/Artemotion/scripts/engine3d/core/GLProgram.py", line 131, in use
    pygl.glUseProgram(self._id)
  File "/Users/dominiklang/Artemotion/venv/lib/python3.11/site-packages/OpenGL/error.py", line 230, in glCheckError
    raise self._errorClass(
OpenGL.error.GLError: GLError(
	err = 1282,
	description = b'invalid operation',
	baseOperation = glUseProgram,
	cArguments = (6,)
)
[2025-10-04 01:47:52.189] {                 Renderable.py: 183} (              UIMain3DSub:   ERROR) - Unable to use the GL program because:
Traceback (most recent call last):
  File "/Users/dominiklang/Artemotion/scripts/engine3d/core/GLProgram.py", line 131, in use
    pygl.glUseProgram(self._id)
  File "/Users/dominiklang/Artemotion/venv/lib/python3.11/site-packages/OpenGL/error.py", line 230, in glCheckError
    raise self._errorClass(
OpenGL.error.GLError: GLError(
	err = 1282,
	description = b'invalid operation',
	baseOperation = glUseProgram,
	cArguments = (6,)
)
[2025-10-04 01:47:52.205] {                 Renderable.py: 183} (              UIMain3DSub:   ERROR) - Unable to use the GL program because:
Traceback (most recent call last):
  File "/Users/dominiklang/Artemotion/scripts/engine3d/core/GLProgram.py", line 131, in use
    pygl.glUseProgram(self._id)
  File "/Users/dominiklang/Artemotion/venv/lib/python3.11/site-packages/OpenGL/error.py", line 230, in glCheckError
    raise self._errorClass(
OpenGL.error.GLError: GLError(
	err = 1282,
	description = b'invalid operation',
	baseOperation = glUseProgram,
	cArguments = (6,)
)
[2025-10-04 01:47:52.222] {                 Renderable.py: 183} (              UIMain3DSub:   ERROR) - Unable to use the GL program because:
Traceback (most recent call last):
  File "/Users/dominiklang/Artemotion/scripts/engine3d/core/GLProgram.py", line 131, in use
    pygl.glUseProgram(self._id)
  File "/Users/dominiklang/Artemotion/venv/lib/python3.11/site-packages/OpenGL/error.py", line 230, in glCheckError
    raise self._errorClass(
OpenGL.error.GLError: GLError(
	err = 1282,
	description = b'invalid operation',
	baseOperation = glUseProgram,
	cArguments = (6,)
)
[2025-10-04 01:47:52.239] {                 Renderable.py: 183} (              UIMain3DSub:   ERROR) - Unable to use the GL program because:
Traceback (most recent call last):
  File "/Users/dominiklang/Artemotion/scripts/engine3d/core/GLProgram.py", line 131, in use
    pygl.glUseProgram(self._id)
  File "/Users/dominiklang/Artemotion/venv/lib/python3.11/site-packages/OpenGL/error.py", line 230, in glCheckError
    raise self._errorClass(
OpenGL.error.GLError: GLError(
	err = 1282,
	description = b'invalid operation',
	baseOperation = glUseProgram,
	cArguments = (6,)
)
[2025-10-04 01:47:52.255] {                 Renderable.py: 183} (              UIMain3DSub:   ERROR) - Unable to use the GL program because:
Traceback (most recent call last):
  File "/Users/dominiklang/Artemotion/scripts/engine3d/core/GLProgram.py", line 131, in use
    pygl.glUseProgram(self._id)
  File "/Users/dominiklang/Artemotion/venv/lib/python3.11/site-packages/OpenGL/error.py", line 230, in glCheckError
    raise self._errorClass(
OpenGL.error.GLError: GLError(
	err = 1282,
	description = b'invalid operation',
	baseOperation = glUseProgram,
	cArguments = (6,)
)
[2025-10-04 01:47:52.272] {                 Renderable.py: 183} (              UIMain3DSub:   ERROR) - Unable to use the GL program because:
Traceback (most recent call last):
  File "/Users/dominiklang/Artemotion/scripts/engine3d/core/GLProgram.py", line 131, in use
    pygl.glUseProgram(self._id)
  File "/Users/dominiklang/Artemotion/venv/lib/python3.11/site-packages/OpenGL/error.py", line 230, in glCheckError
    raise self._errorClass(
OpenGL.error.GLError: GLError(
	err = 1282,
	description = b'invalid operation',
	baseOperation = glUseProgram,
	cArguments = (6,)
)
[2025-10-04 01:47:52.288] {                 Renderable.py: 183} (              UIMain3DSub:   ERROR) - Unable to use the GL program because:
Traceback (most recent call last):
  File "/Users/dominiklang/Artemotion/scripts/engine3d/core/GLProgram.py", line 131, in use
    pygl.glUseProgram(self._id)
  File "/Users/dominiklang/Artemotion/venv/lib/python3.11/site-packages/OpenGL/error.py", line 230, in glCheckError
    raise self._errorClass(
OpenGL.error.GLError: GLError(
	err = 1282,
	description = b'invalid operation',
	baseOperation = glUseProgram,
	cArguments = (6,)
)
[2025-10-04 01:47:52.305] {                 Renderable.py: 183} (              UIMain3DSub:   ERROR) - Unable to use the GL program because:
Traceback (most recent call last):
  File "/Users/dominiklang/Artemotion/scripts/engine3d/core/GLProgram.py", line 131, in use
    pygl.glUseProgram(self._id)
  File "/Users/dominiklang/Artemotion/venv/lib/python3.11/site-packages/OpenGL/error.py", line 230, in glCheckError
    raise self._errorClass(
OpenGL.error.GLError: GLError(
	err = 1282,
	description = b'invalid operation',
	baseOperation = glUseProgram,
	cArguments = (6,)
)
[2025-10-04 01:47:52.322] {                 Renderable.py: 183} (              UIMain3DSub:   ERROR) - Unable to use the GL program because:
Traceback (most recent call last):
  File "/Users/dominiklang/Artemotion/scripts/engine3d/core/GLProgram.py", line 131, in use
    pygl.glUseProgram(self._id)
  File "/Users/dominiklang/Artemotion/venv/lib/python3.11/site-packages/OpenGL/error.py", line 230, in glCheckError
    raise self._errorClass(
OpenGL.error.GLError: GLError(
	err = 1282,
	description = b'invalid operation',
	baseOperation = glUseProgram,
	cArguments = (6,)
)
[2025-10-04 01:47:52.339] {                 Renderable.py: 183} (              UIMain3DSub:   ERROR) - Unable to use the GL program because:
Traceback (most recent call last):
  File "/Users/dominiklang/Artemotion/scripts/engine3d/core/GLProgram.py", line 131, in use
    pygl.glUseProgram(self._id)
  File "/Users/dominiklang/Artemotion/venv/lib/python3.11/site-packages/OpenGL/error.py", line 230, in glCheckError
    raise self._errorClass(
OpenGL.error.GLError: GLError(
	err = 1282,
	description = b'invalid operation',
	baseOperation = glUseProgram,
	cArguments = (6,)
)
[2025-10-04 01:47:52.355] {                 Renderable.py: 183} (              UIMain3DSub:   ERROR) - Unable to use the GL program because:
Traceback (most recent call last):
  File "/Users/dominiklang/Artemotion/scripts/engine3d/core/GLProgram.py", line 131, in use
    pygl.glUseProgram(self._id)
  File "/Users/dominiklang/Artemotion/venv/lib/python3.11/site-packages/OpenGL/error.py", line 230, in glCheckError
    raise self._errorClass(
OpenGL.error.GLError: GLError(
	err = 1282,
	description = b'invalid operation',
	baseOperation = glUseProgram,
	cArguments = (6,)
)
[2025-10-04 01:47:52.361] {                 Renderable.py: 183} (              UIMain3DSub:   ERROR) - Unable to use the GL program because:
Traceback (most recent call last):
  File "/Users/dominiklang/Artemotion/scripts/engine3d/core/GLProgram.py", line 131, in use
    pygl.glUseProgram(self._id)
  File "/Users/dominiklang/Artemotion/venv/lib/python3.11/site-packages/OpenGL/error.py", line 230, in glCheckError
    raise self._errorClass(
OpenGL.error.GLError: GLError(
	err = 1282,
	description = b'invalid operation',
	baseOperation = glUseProgram,
	cArguments = (6,)
)
[2025-10-04 01:47:52.372] {                 Renderable.py: 183} (              UIMain3DSub:   ERROR) - Unable to use the GL program because:
Traceback (most recent call last):
  File "/Users/dominiklang/Artemotion/scripts/engine3d/core/GLProgram.py", line 131, in use
    pygl.glUseProgram(self._id)
  File "/Users/dominiklang/Artemotion/venv/lib/python3.11/site-packages/OpenGL/error.py", line 230, in glCheckError
    raise self._errorClass(
OpenGL.error.GLError: GLError(
	err = 1282,
	description = b'invalid operation',
	baseOperation = glUseProgram,
	cArguments = (6,)
)
[2025-10-04 01:47:52.384] {                 Renderable.py: 183} (              UIMain3DSub:   ERROR) - Unable to use the GL program because:
Traceback (most recent call last):
  File "/Users/dominiklang/Artemotion/scripts/engine3d/core/GLProgram.py", line 131, in use
    pygl.glUseProgram(self._id)
  File "/Users/dominiklang/Artemotion/venv/lib/python3.11/site-packages/OpenGL/error.py", line 230, in glCheckError
    raise self._errorClass(
OpenGL.error.GLError: GLError(
	err = 1282,
	description = b'invalid operation',
	baseOperation = glUseProgram,
	cArguments = (6,)
)
[2025-10-04 01:47:52.408] {                 Renderable.py: 183} (              UIMain3DSub:   ERROR) - Unable to use the GL program because:
Traceback (most recent call last):
  File "/Users/dominiklang/Artemotion/scripts/engine3d/core/GLProgram.py", line 131, in use
    pygl.glUseProgram(self._id)
  File "/Users/dominiklang/Artemotion/venv/lib/python3.11/site-packages/OpenGL/error.py", line 230, in glCheckError
    raise self._errorClass(
OpenGL.error.GLError: GLError(
	err = 1282,
	description = b'invalid operation',
	baseOperation = glUseProgram,
	cArguments = (6,)
)
[2025-10-04 01:47:52.410] {                 Renderable.py: 183} (              UIMain3DSub:   ERROR) - Unable to use the GL program because:
Traceback (most recent call last):
  File "/Users/dominiklang/Artemotion/scripts/engine3d/core/GLProgram.py", line 131, in use
    pygl.glUseProgram(self._id)
  File "/Users/dominiklang/Artemotion/venv/lib/python3.11/site-packages/OpenGL/error.py", line 230, in glCheckError
    raise self._errorClass(
OpenGL.error.GLError: GLError(
	err = 1282,
	description = b'invalid operation',
	baseOperation = glUseProgram,
	cArguments = (6,)
)
[2025-10-04 01:47:52.422] {                 Renderable.py: 183} (              UIMain3DSub:   ERROR) - Unable to use the GL program because:
Traceback (most recent call last):
  File "/Users/dominiklang/Artemotion/scripts/engine3d/core/GLProgram.py", line 131, in use
    pygl.glUseProgram(self._id)
  File "/Users/dominiklang/Artemotion/venv/lib/python3.11/site-packages/OpenGL/error.py", line 230, in glCheckError
    raise self._errorClass(
OpenGL.error.GLError: GLError(
	err = 1282,
	description = b'invalid operation',
	baseOperation = glUseProgram,
	cArguments = (6,)
)
[2025-10-04 01:47:52.427] {                 Renderable.py: 183} (              UIMain3DSub:   ERROR) - Unable to use the GL program because:
Traceback (most recent call last):
  File "/Users/dominiklang/Artemotion/scripts/engine3d/core/GLProgram.py", line 131, in use
    pygl.glUseProgram(self._id)
  File "/Users/dominiklang/Artemotion/venv/lib/python3.11/site-packages/OpenGL/error.py", line 230, in glCheckError
    raise self._errorClass(
OpenGL.error.GLError: GLError(
	err = 1282,
	description = b'invalid operation',
	baseOperation = glUseProgram,
	cArguments = (6,)
)
[2025-10-04 01:47:52.470] {                 Renderable.py: 183} (              UIMain3DSub:   ERROR) - Unable to use the GL program because:
Traceback (most recent call last):
  File "/Users/dominiklang/Artemotion/scripts/engine3d/core/GLProgram.py", line 131, in use
    pygl.glUseProgram(self._id)
  File "/Users/dominiklang/Artemotion/venv/lib/python3.11/site-packages/OpenGL/error.py", line 230, in glCheckError
    raise self._errorClass(
OpenGL.error.GLError: GLError(
	err = 1282,
	description = b'invalid operation',
	baseOperation = glUseProgram,
	cArguments = (6,)
)
[2025-10-04 01:47:52.475] {                 Renderable.py: 183} (              UIMain3DSub:   ERROR) - Unable to use the GL program because:
Traceback (most recent call last):
  File "/Users/dominiklang/Artemotion/scripts/engine3d/core/GLProgram.py", line 131, in use
    pygl.glUseProgram(self._id)
  File "/Users/dominiklang/Artemotion/venv/lib/python3.11/site-packages/OpenGL/error.py", line 230, in glCheckError
    raise self._errorClass(
OpenGL.error.GLError: GLError(
	err = 1282,
	description = b'invalid operation',
	baseOperation = glUseProgram,
	cArguments = (6,)
)
[2025-10-04 01:47:52.477] {                 Renderable.py: 183} (              UIMain3DSub:   ERROR) - Unable to use the GL program because:
Traceback (most recent call last):
  File "/Users/dominiklang/Artemotion/scripts/engine3d/core/GLProgram.py", line 131, in use
    pygl.glUseProgram(self._id)
  File "/Users/dominiklang/Artemotion/venv/lib/python3.11/site-packages/OpenGL/error.py", line 230, in glCheckError
    raise self._errorClass(
OpenGL.error.GLError: GLError(
	err = 1282,
	description = b'invalid operation',
	baseOperation = glUseProgram,
	cArguments = (6,)
)
[2025-10-04 01:47:52.489] {                 Renderable.py: 183} (              UIMain3DSub:   ERROR) - Unable to use the GL program because:
Traceback (most recent call last):
  File "/Users/dominiklang/Artemotion/scripts/engine3d/core/GLProgram.py", line 131, in use
    pygl.glUseProgram(self._id)
  File "/Users/dominiklang/Artemotion/venv/lib/python3.11/site-packages/OpenGL/error.py", line 230, in glCheckError
    raise self._errorClass(
OpenGL.error.GLError: GLError(
	err = 1282,
	description = b'invalid operation',
	baseOperation = glUseProgram,
	cArguments = (6,)
)
[2025-10-04 01:47:52.505] {                 Renderable.py: 183} (              UIMain3DSub:   ERROR) - Unable to use the GL program because:
Traceback (most recent call last):
  File "/Users/dominiklang/Artemotion/scripts/engine3d/core/GLProgram.py", line 131, in use
    pygl.glUseProgram(self._id)
  File "/Users/dominiklang/Artemotion/venv/lib/python3.11/site-packages/OpenGL/error.py", line 230, in glCheckError
    raise self._errorClass(
OpenGL.error.GLError: GLError(
	err = 1282,
	description = b'invalid operation',
	baseOperation = glUseProgram,
	cArguments = (6,)
)
[2025-10-04 01:47:52.522] {                 Renderable.py: 183} (              UIMain3DSub:   ERROR) - Unable to use the GL program because:
Traceback (most recent call last):
  File "/Users/dominiklang/Artemotion/scripts/engine3d/core/GLProgram.py", line 131, in use
    pygl.glUseProgram(self._id)
  File "/Users/dominiklang/Artemotion/venv/lib/python3.11/site-packages/OpenGL/error.py", line 230, in glCheckError
    raise self._errorClass(
OpenGL.error.GLError: GLError(
	err = 1282,
	description = b'invalid operation',
	baseOperation = glUseProgram,
	cArguments = (6,)
)
[2025-10-04 01:47:52.538] {                 Renderable.py: 183} (              UIMain3DSub:   ERROR) - Unable to use the GL program because:
Traceback (most recent call last):
  File "/Users/dominiklang/Artemotion/scripts/engine3d/core/GLProgram.py", line 131, in use
    pygl.glUseProgram(self._id)
  File "/Users/dominiklang/Artemotion/venv/lib/python3.11/site-packages/OpenGL/error.py", line 230, in glCheckError
    raise self._errorClass(
OpenGL.error.GLError: GLError(
	err = 1282,
	description = b'invalid operation',
	baseOperation = glUseProgram,
	cArguments = (6,)
)
[2025-10-04 01:47:52.555] {                 Renderable.py: 183} (              UIMain3DSub:   ERROR) - Unable to use the GL program because:
Traceback (most recent call last):
  File "/Users/dominiklang/Artemotion/scripts/engine3d/core/GLProgram.py", line 131, in use
    pygl.glUseProgram(self._id)
  File "/Users/dominiklang/Artemotion/venv/lib/python3.11/site-packages/OpenGL/error.py", line 230, in glCheckError
    raise self._errorClass(
OpenGL.error.GLError: GLError(
	err = 1282,
	description = b'invalid operation',
	baseOperation = glUseProgram,
	cArguments = (6,)
)
[2025-10-04 01:47:52.572] {                 Renderable.py: 183} (              UIMain3DSub:   ERROR) - Unable to use the GL program because:
Traceback (most recent call last):
  File "/Users/dominiklang/Artemotion/scripts/engine3d/core/GLProgram.py", line 131, in use
    pygl.glUseProgram(self._id)
  File "/Users/dominiklang/Artemotion/venv/lib/python3.11/site-packages/OpenGL/error.py", line 230, in glCheckError
    raise self._errorClass(
OpenGL.error.GLError: GLError(
	err = 1282,
	description = b'invalid operation',
	baseOperation = glUseProgram,
	cArguments = (6,)
)
[2025-10-04 01:47:52.622] {                 Renderable.py: 183} (              UIMain3DSub:   ERROR) - Unable to use the GL program because:
Traceback (most recent call last):
  File "/Users/dominiklang/Artemotion/scripts/engine3d/core/GLProgram.py", line 131, in use
    pygl.glUseProgram(self._id)
  File "/Users/dominiklang/Artemotion/venv/lib/python3.11/site-packages/OpenGL/error.py", line 230, in glCheckError
    raise self._errorClass(
OpenGL.error.GLError: GLError(
	err = 1282,
	description = b'invalid operation',
	baseOperation = glUseProgram,
	cArguments = (6,)
)
[2025-10-04 01:47:52.639] {                 Renderable.py: 183} (              UIMain3DSub:   ERROR) - Unable to use the GL program because:
Traceback (most recent call last):
  File "/Users/dominiklang/Artemotion/scripts/engine3d/core/GLProgram.py", line 131, in use
    pygl.glUseProgram(self._id)
  File "/Users/dominiklang/Artemotion/venv/lib/python3.11/site-packages/OpenGL/error.py", line 230, in glCheckError
    raise self._errorClass(
OpenGL.error.GLError: GLError(
	err = 1282,
	description = b'invalid operation',
	baseOperation = glUseProgram,
	cArguments = (6,)
)
[2025-10-04 01:47:52.655] {                 Renderable.py: 183} (              UIMain3DSub:   ERROR) - Unable to use the GL program because:
Traceback (most recent call last):
  File "/Users/dominiklang/Artemotion/scripts/engine3d/core/GLProgram.py", line 131, in use
    pygl.glUseProgram(self._id)
  File "/Users/dominiklang/Artemotion/venv/lib/python3.11/site-packages/OpenGL/error.py", line 230, in glCheckError
    raise self._errorClass(
OpenGL.error.GLError: GLError(
	err = 1282,
	description = b'invalid operation',
	baseOperation = glUseProgram,
	cArguments = (6,)
)
[2025-10-04 01:47:52.659] {                 Renderable.py: 183} (              UIMain3DSub:   ERROR) - Unable to use the GL program because:
Traceback (most recent call last):
  File "/Users/dominiklang/Artemotion/scripts/engine3d/core/GLProgram.py", line 131, in use
    pygl.glUseProgram(self._id)
  File "/Users/dominiklang/Artemotion/venv/lib/python3.11/site-packages/OpenGL/error.py", line 230, in glCheckError
    raise self._errorClass(
OpenGL.error.GLError: GLError(
	err = 1282,
	description = b'invalid operation',
	baseOperation = glUseProgram,
	cArguments = (6,)
)
[2025-10-04 01:47:52.672] {                 Renderable.py: 183} (              UIMain3DSub:   ERROR) - Unable to use the GL program because:
Traceback (most recent call last):
  File "/Users/dominiklang/Artemotion/scripts/engine3d/core/GLProgram.py", line 131, in use
    pygl.glUseProgram(self._id)
  File "/Users/dominiklang/Artemotion/venv/lib/python3.11/site-packages/OpenGL/error.py", line 230, in glCheckError
    raise self._errorClass(
OpenGL.error.GLError: GLError(
	err = 1282,
	description = b'invalid operation',
	baseOperation = glUseProgram,
	cArguments = (6,)
)
[2025-10-04 01:47:52.676] {                 Renderable.py: 183} (              UIMain3DSub:   ERROR) - Unable to use the GL program because:
Traceback (most recent call last):
  File "/Users/dominiklang/Artemotion/scripts/engine3d/core/GLProgram.py", line 131, in use
    pygl.glUseProgram(self._id)
  File "/Users/dominiklang/Artemotion/venv/lib/python3.11/site-packages/OpenGL/error.py", line 230, in glCheckError
    raise self._errorClass(
OpenGL.error.GLError: GLError(
	err = 1282,
	description = b'invalid operation',
	baseOperation = glUseProgram,
	cArguments = (6,)
)
[2025-10-04 01:47:52.688] {                 Renderable.py: 183} (              UIMain3DSub:   ERROR) - Unable to use the GL program because:
Traceback (most recent call last):
  File "/Users/dominiklang/Artemotion/scripts/engine3d/core/GLProgram.py", line 131, in use
    pygl.glUseProgram(self._id)
  File "/Users/dominiklang/Artemotion/venv/lib/python3.11/site-packages/OpenGL/error.py", line 230, in glCheckError
    raise self._errorClass(
OpenGL.error.GLError: GLError(
	err = 1282,
	description = b'invalid operation',
	baseOperation = glUseProgram,
	cArguments = (6,)
)
[2025-10-04 01:47:52.694] {                 Renderable.py: 183} (              UIMain3DSub:   ERROR) - Unable to use the GL program because:
Traceback (most recent call last):
  File "/Users/dominiklang/Artemotion/scripts/engine3d/core/GLProgram.py", line 131, in use
    pygl.glUseProgram(self._id)
  File "/Users/dominiklang/Artemotion/venv/lib/python3.11/site-packages/OpenGL/error.py", line 230, in glCheckError
    raise self._errorClass(
OpenGL.error.GLError: GLError(
	err = 1282,
	description = b'invalid operation',
	baseOperation = glUseProgram,
	cArguments = (6,)
)
[2025-10-04 01:47:52.705] {                 Renderable.py: 183} (              UIMain3DSub:   ERROR) - Unable to use the GL program because:
Traceback (most recent call last):
  File "/Users/dominiklang/Artemotion/scripts/engine3d/core/GLProgram.py", line 131, in use
    pygl.glUseProgram(self._id)
  File "/Users/dominiklang/Artemotion/venv/lib/python3.11/site-packages/OpenGL/error.py", line 230, in glCheckError
    raise self._errorClass(
OpenGL.error.GLError: GLError(
	err = 1282,
	description = b'invalid operation',
	baseOperation = glUseProgram,
	cArguments = (6,)
)
[2025-10-04 01:47:52.709] {                 Renderable.py: 183} (              UIMain3DSub:   ERROR) - Unable to use the GL program because:
Traceback (most recent call last):
  File "/Users/dominiklang/Artemotion/scripts/engine3d/core/GLProgram.py", line 131, in use
    pygl.glUseProgram(self._id)
  File "/Users/dominiklang/Artemotion/venv/lib/python3.11/site-packages/OpenGL/error.py", line 230, in glCheckError
    raise self._errorClass(
OpenGL.error.GLError: GLError(
	err = 1282,
	description = b'invalid operation',
	baseOperation = glUseProgram,
	cArguments = (6,)
)
[2025-10-04 01:47:52.722] {                 Renderable.py: 183} (              UIMain3DSub:   ERROR) - Unable to use the GL program because:
Traceback (most recent call last):
  File "/Users/dominiklang/Artemotion/scripts/engine3d/core/GLProgram.py", line 131, in use
    pygl.glUseProgram(self._id)
  File "/Users/dominiklang/Artemotion/venv/lib/python3.11/site-packages/OpenGL/error.py", line 230, in glCheckError
    raise self._errorClass(
OpenGL.error.GLError: GLError(
	err = 1282,
	description = b'invalid operation',
	baseOperation = glUseProgram,
	cArguments = (6,)
)
[2025-10-04 01:47:52.726] {                 Renderable.py: 183} (              UIMain3DSub:   ERROR) - Unable to use the GL program because:
Traceback (most recent call last):
  File "/Users/dominiklang/Artemotion/scripts/engine3d/core/GLProgram.py", line 131, in use
    pygl.glUseProgram(self._id)
  File "/Users/dominiklang/Artemotion/venv/lib/python3.11/site-packages/OpenGL/error.py", line 230, in glCheckError
    raise self._errorClass(
OpenGL.error.GLError: GLError(
	err = 1282,
	description = b'invalid operation',
	baseOperation = glUseProgram,
	cArguments = (6,)
)
[2025-10-04 01:47:52.739] {                 Renderable.py: 183} (              UIMain3DSub:   ERROR) - Unable to use the GL program because:
Traceback (most recent call last):
  File "/Users/dominiklang/Artemotion/scripts/engine3d/core/GLProgram.py", line 131, in use
    pygl.glUseProgram(self._id)
  File "/Users/dominiklang/Artemotion/venv/lib/python3.11/site-packages/OpenGL/error.py", line 230, in glCheckError
    raise self._errorClass(
OpenGL.error.GLError: GLError(
	err = 1282,
	description = b'invalid operation',
	baseOperation = glUseProgram,
	cArguments = (6,)
)
[2025-10-04 01:47:52.743] {                 Renderable.py: 183} (              UIMain3DSub:   ERROR) - Unable to use the GL program because:
Traceback (most recent call last):
  File "/Users/dominiklang/Artemotion/scripts/engine3d/core/GLProgram.py", line 131, in use
    pygl.glUseProgram(self._id)
  File "/Users/dominiklang/Artemotion/venv/lib/python3.11/site-packages/OpenGL/error.py", line 230, in glCheckError
    raise self._errorClass(
OpenGL.error.GLError: GLError(
	err = 1282,
	description = b'invalid operation',
	baseOperation = glUseProgram,
	cArguments = (6,)
)
[2025-10-04 01:47:52.755] {                 Renderable.py: 183} (              UIMain3DSub:   ERROR) - Unable to use the GL program because:
Traceback (most recent call last):
  File "/Users/dominiklang/Artemotion/scripts/engine3d/core/GLProgram.py", line 131, in use
    pygl.glUseProgram(self._id)
  File "/Users/dominiklang/Artemotion/venv/lib/python3.11/site-packages/OpenGL/error.py", line 230, in glCheckError
    raise self._errorClass(
OpenGL.error.GLError: GLError(
	err = 1282,
	description = b'invalid operation',
	baseOperation = glUseProgram,
	cArguments = (6,)
)
[2025-10-04 01:47:52.772] {                 Renderable.py: 183} (              UIMain3DSub:   ERROR) - Unable to use the GL program because:
Traceback (most recent call last):
  File "/Users/dominiklang/Artemotion/scripts/engine3d/core/GLProgram.py", line 131, in use
    pygl.glUseProgram(self._id)
  File "/Users/dominiklang/Artemotion/venv/lib/python3.11/site-packages/OpenGL/error.py", line 230, in glCheckError
    raise self._errorClass(
OpenGL.error.GLError: GLError(
	err = 1282,
	description = b'invalid operation',
	baseOperation = glUseProgram,
	cArguments = (6,)
)
[2025-10-04 01:47:52.789] {                 Renderable.py: 183} (              UIMain3DSub:   ERROR) - Unable to use the GL program because:
Traceback (most recent call last):
  File "/Users/dominiklang/Artemotion/scripts/engine3d/core/GLProgram.py", line 131, in use
    pygl.glUseProgram(self._id)
  File "/Users/dominiklang/Artemotion/venv/lib/python3.11/site-packages/OpenGL/error.py", line 230, in glCheckError
    raise self._errorClass(
OpenGL.error.GLError: GLError(
	err = 1282,
	description = b'invalid operation',
	baseOperation = glUseProgram,
	cArguments = (6,)
)
[2025-10-04 01:47:52.806] {                 Renderable.py: 183} (              UIMain3DSub:   ERROR) - Unable to use the GL program because:
Traceback (most recent call last):
  File "/Users/dominiklang/Artemotion/scripts/engine3d/core/GLProgram.py", line 131, in use
    pygl.glUseProgram(self._id)
  File "/Users/dominiklang/Artemotion/venv/lib/python3.11/site-packages/OpenGL/error.py", line 230, in glCheckError
    raise self._errorClass(
OpenGL.error.GLError: GLError(
	err = 1282,
	description = b'invalid operation',
	baseOperation = glUseProgram,
	cArguments = (6,)
)
[2025-10-04 01:47:52.822] {                 Renderable.py: 183} (              UIMain3DSub:   ERROR) - Unable to use the GL program because:
Traceback (most recent call last):
  File "/Users/dominiklang/Artemotion/scripts/engine3d/core/GLProgram.py", line 131, in use
    pygl.glUseProgram(self._id)
  File "/Users/dominiklang/Artemotion/venv/lib/python3.11/site-packages/OpenGL/error.py", line 230, in glCheckError
    raise self._errorClass(
OpenGL.error.GLError: GLError(
	err = 1282,
	description = b'invalid operation',
	baseOperation = glUseProgram,
	cArguments = (6,)
)
[2025-10-04 01:47:52.839] {                 Renderable.py: 183} (              UIMain3DSub:   ERROR) - Unable to use the GL program because:
Traceback (most recent call last):
  File "/Users/dominiklang/Artemotion/scripts/engine3d/core/GLProgram.py", line 131, in use
    pygl.glUseProgram(self._id)
  File "/Users/dominiklang/Artemotion/venv/lib/python3.11/site-packages/OpenGL/error.py", line 230, in glCheckError
    raise self._errorClass(
OpenGL.error.GLError: GLError(
	err = 1282,
	description = b'invalid operation',
	baseOperation = glUseProgram,
	cArguments = (6,)
)
[2025-10-04 01:47:53.243] {                 Renderable.py: 183} (              UIMain3DSub:   ERROR) - Unable to use the GL program because:
Traceback (most recent call last):
  File "/Users/dominiklang/Artemotion/scripts/engine3d/core/GLProgram.py", line 131, in use
    pygl.glUseProgram(self._id)
  File "/Users/dominiklang/Artemotion/venv/lib/python3.11/site-packages/OpenGL/error.py", line 230, in glCheckError
    raise self._errorClass(
OpenGL.error.GLError: GLError(
	err = 1282,
	description = b'invalid operation',
	baseOperation = glUseProgram,
	cArguments = (6,)
)
[2025-10-04 01:47:53.289] {                 Renderable.py: 183} (              UIMain3DSub:   ERROR) - Unable to use the GL program because:
Traceback (most recent call last):
  File "/Users/dominiklang/Artemotion/scripts/engine3d/core/GLProgram.py", line 131, in use
    pygl.glUseProgram(self._id)
  File "/Users/dominiklang/Artemotion/venv/lib/python3.11/site-packages/OpenGL/error.py", line 230, in glCheckError
    raise self._errorClass(
OpenGL.error.GLError: GLError(
	err = 1282,
	description = b'invalid operation',
	baseOperation = glUseProgram,
	cArguments = (6,)
)
[2025-10-04 01:47:53.293] {                 Renderable.py: 183} (              UIMain3DSub:   ERROR) - Unable to use the GL program because:
Traceback (most recent call last):
  File "/Users/dominiklang/Artemotion/scripts/engine3d/core/GLProgram.py", line 131, in use
    pygl.glUseProgram(self._id)
  File "/Users/dominiklang/Artemotion/venv/lib/python3.11/site-packages/OpenGL/error.py", line 230, in glCheckError
    raise self._errorClass(
OpenGL.error.GLError: GLError(
	err = 1282,
	description = b'invalid operation',
	baseOperation = glUseProgram,
	cArguments = (6,)
)
[2025-10-04 01:47:53.305] {                 Renderable.py: 183} (              UIMain3DSub:   ERROR) - Unable to use the GL program because:
Traceback (most recent call last):
  File "/Users/dominiklang/Artemotion/scripts/engine3d/core/GLProgram.py", line 131, in use
    pygl.glUseProgram(self._id)
  File "/Users/dominiklang/Artemotion/venv/lib/python3.11/site-packages/OpenGL/error.py", line 230, in glCheckError
    raise self._errorClass(
OpenGL.error.GLError: GLError(
	err = 1282,
	description = b'invalid operation',
	baseOperation = glUseProgram,
	cArguments = (6,)
)
[2025-10-04 01:47:53.337] {                 Renderable.py: 183} (              UIMain3DSub:   ERROR) - Unable to use the GL program because:
Traceback (most recent call last):
  File "/Users/dominiklang/Artemotion/scripts/engine3d/core/GLProgram.py", line 131, in use
    pygl.glUseProgram(self._id)
  File "/Users/dominiklang/Artemotion/venv/lib/python3.11/site-packages/OpenGL/error.py", line 230, in glCheckError
    raise self._errorClass(
OpenGL.error.GLError: GLError(
	err = 1282,
	description = b'invalid operation',
	baseOperation = glUseProgram,
	cArguments = (6,)
)
[2025-10-04 01:47:53.339] {                 Renderable.py: 183} (              UIMain3DSub:   ERROR) - Unable to use the GL program because:
Traceback (most recent call last):
  File "/Users/dominiklang/Artemotion/scripts/engine3d/core/GLProgram.py", line 131, in use
    pygl.glUseProgram(self._id)
  File "/Users/dominiklang/Artemotion/venv/lib/python3.11/site-packages/OpenGL/error.py", line 230, in glCheckError
    raise self._errorClass(
OpenGL.error.GLError: GLError(
	err = 1282,
	description = b'invalid operation',
	baseOperation = glUseProgram,
	cArguments = (6,)
)
[2025-10-04 01:47:53.355] {                 Renderable.py: 183} (              UIMain3DSub:   ERROR) - Unable to use the GL program because:
Traceback (most recent call last):
  File "/Users/dominiklang/Artemotion/scripts/engine3d/core/GLProgram.py", line 131, in use
    pygl.glUseProgram(self._id)
  File "/Users/dominiklang/Artemotion/venv/lib/python3.11/site-packages/OpenGL/error.py", line 230, in glCheckError
    raise self._errorClass(
OpenGL.error.GLError: GLError(
	err = 1282,
	description = b'invalid operation',
	baseOperation = glUseProgram,
	cArguments = (6,)
)
[2025-10-04 01:47:53.372] {                 Renderable.py: 183} (              UIMain3DSub:   ERROR) - Unable to use the GL program because:
Traceback (most recent call last):
  File "/Users/dominiklang/Artemotion/scripts/engine3d/core/GLProgram.py", line 131, in use
    pygl.glUseProgram(self._id)
  File "/Users/dominiklang/Artemotion/venv/lib/python3.11/site-packages/OpenGL/error.py", line 230, in glCheckError
    raise self._errorClass(
OpenGL.error.GLError: GLError(
	err = 1282,
	description = b'invalid operation',
	baseOperation = glUseProgram,
	cArguments = (6,)
)
[2025-10-04 01:47:53.389] {                 Renderable.py: 183} (              UIMain3DSub:   ERROR) - Unable to use the GL program because:
Traceback (most recent call last):
  File "/Users/dominiklang/Artemotion/scripts/engine3d/core/GLProgram.py", line 131, in use
    pygl.glUseProgram(self._id)
  File "/Users/dominiklang/Artemotion/venv/lib/python3.11/site-packages/OpenGL/error.py", line 230, in glCheckError
    raise self._errorClass(
OpenGL.error.GLError: GLError(
	err = 1282,
	description = b'invalid operation',
	baseOperation = glUseProgram,
	cArguments = (6,)
)
[2025-10-04 01:47:53.405] {                 Renderable.py: 183} (              UIMain3DSub:   ERROR) - Unable to use the GL program because:
Traceback (most recent call last):
  File "/Users/dominiklang/Artemotion/scripts/engine3d/core/GLProgram.py", line 131, in use
    pygl.glUseProgram(self._id)
  File "/Users/dominiklang/Artemotion/venv/lib/python3.11/site-packages/OpenGL/error.py", line 230, in glCheckError
    raise self._errorClass(
OpenGL.error.GLError: GLError(
	err = 1282,
	description = b'invalid operation',
	baseOperation = glUseProgram,
	cArguments = (6,)
)
[2025-10-04 01:47:53.451] {                 Renderable.py: 183} (              UIMain3DSub:   ERROR) - Unable to use the GL program because:
Traceback (most recent call last):
  File "/Users/dominiklang/Artemotion/scripts/engine3d/core/GLProgram.py", line 131, in use
    pygl.glUseProgram(self._id)
  File "/Users/dominiklang/Artemotion/venv/lib/python3.11/site-packages/OpenGL/error.py", line 230, in glCheckError
    raise self._errorClass(
OpenGL.error.GLError: GLError(
	err = 1282,
	description = b'invalid operation',
	baseOperation = glUseProgram,
	cArguments = (6,)
)
[2025-10-04 01:47:53.458] {                 Renderable.py: 183} (              UIMain3DSub:   ERROR) - Unable to use the GL program because:
Traceback (most recent call last):
  File "/Users/dominiklang/Artemotion/scripts/engine3d/core/GLProgram.py", line 131, in use
    pygl.glUseProgram(self._id)
  File "/Users/dominiklang/Artemotion/venv/lib/python3.11/site-packages/OpenGL/error.py", line 230, in glCheckError
    raise self._errorClass(
OpenGL.error.GLError: GLError(
	err = 1282,
	description = b'invalid operation',
	baseOperation = glUseProgram,
	cArguments = (6,)
)
[2025-10-04 01:47:53.472] {                 Renderable.py: 183} (              UIMain3DSub:   ERROR) - Unable to use the GL program because:
Traceback (most recent call last):
  File "/Users/dominiklang/Artemotion/scripts/engine3d/core/GLProgram.py", line 131, in use
    pygl.glUseProgram(self._id)
  File "/Users/dominiklang/Artemotion/venv/lib/python3.11/site-packages/OpenGL/error.py", line 230, in glCheckError
    raise self._errorClass(
OpenGL.error.GLError: GLError(
	err = 1282,
	description = b'invalid operation',
	baseOperation = glUseProgram,
	cArguments = (6,)
)
[2025-10-04 01:47:53.489] {                 Renderable.py: 183} (              UIMain3DSub:   ERROR) - Unable to use the GL program because:
Traceback (most recent call last):
  File "/Users/dominiklang/Artemotion/scripts/engine3d/core/GLProgram.py", line 131, in use
    pygl.glUseProgram(self._id)
  File "/Users/dominiklang/Artemotion/venv/lib/python3.11/site-packages/OpenGL/error.py", line 230, in glCheckError
    raise self._errorClass(
OpenGL.error.GLError: GLError(
	err = 1282,
	description = b'invalid operation',
	baseOperation = glUseProgram,
	cArguments = (6,)
)
[2025-10-04 01:47:53.505] {                 Renderable.py: 183} (              UIMain3DSub:   ERROR) - Unable to use the GL program because:
Traceback (most recent call last):
  File "/Users/dominiklang/Artemotion/scripts/engine3d/core/GLProgram.py", line 131, in use
    pygl.glUseProgram(self._id)
  File "/Users/dominiklang/Artemotion/venv/lib/python3.11/site-packages/OpenGL/error.py", line 230, in glCheckError
    raise self._errorClass(
OpenGL.error.GLError: GLError(
	err = 1282,
	description = b'invalid operation',
	baseOperation = glUseProgram,
	cArguments = (6,)
)
[2025-10-04 01:47:53.509] {                 Renderable.py: 183} (              UIMain3DSub:   ERROR) - Unable to use the GL program because:
Traceback (most recent call last):
  File "/Users/dominiklang/Artemotion/scripts/engine3d/core/GLProgram.py", line 131, in use
    pygl.glUseProgram(self._id)
  File "/Users/dominiklang/Artemotion/venv/lib/python3.11/site-packages/OpenGL/error.py", line 230, in glCheckError
    raise self._errorClass(
OpenGL.error.GLError: GLError(
	err = 1282,
	description = b'invalid operation',
	baseOperation = glUseProgram,
	cArguments = (6,)
)
[2025-10-04 01:47:53.522] {                 Renderable.py: 183} (              UIMain3DSub:   ERROR) - Unable to use the GL program because:
Traceback (most recent call last):
  File "/Users/dominiklang/Artemotion/scripts/engine3d/core/GLProgram.py", line 131, in use
    pygl.glUseProgram(self._id)
  File "/Users/dominiklang/Artemotion/venv/lib/python3.11/site-packages/OpenGL/error.py", line 230, in glCheckError
    raise self._errorClass(
OpenGL.error.GLError: GLError(
	err = 1282,
	description = b'invalid operation',
	baseOperation = glUseProgram,
	cArguments = (6,)
)
[2025-10-04 01:47:53.526] {                 Renderable.py: 183} (              UIMain3DSub:   ERROR) - Unable to use the GL program because:
Traceback (most recent call last):
  File "/Users/dominiklang/Artemotion/scripts/engine3d/core/GLProgram.py", line 131, in use
    pygl.glUseProgram(self._id)
  File "/Users/dominiklang/Artemotion/venv/lib/python3.11/site-packages/OpenGL/error.py", line 230, in glCheckError
    raise self._errorClass(
OpenGL.error.GLError: GLError(
	err = 1282,
	description = b'invalid operation',
	baseOperation = glUseProgram,
	cArguments = (6,)
)
[2025-10-04 01:47:53.538] {                 Renderable.py: 183} (              UIMain3DSub:   ERROR) - Unable to use the GL program because:
Traceback (most recent call last):
  File "/Users/dominiklang/Artemotion/scripts/engine3d/core/GLProgram.py", line 131, in use
    pygl.glUseProgram(self._id)
  File "/Users/dominiklang/Artemotion/venv/lib/python3.11/site-packages/OpenGL/error.py", line 230, in glCheckError
    raise self._errorClass(
OpenGL.error.GLError: GLError(
	err = 1282,
	description = b'invalid operation',
	baseOperation = glUseProgram,
	cArguments = (6,)
)
[2025-10-04 01:47:53.543] {                 Renderable.py: 183} (              UIMain3DSub:   ERROR) - Unable to use the GL program because:
Traceback (most recent call last):
  File "/Users/dominiklang/Artemotion/scripts/engine3d/core/GLProgram.py", line 131, in use
    pygl.glUseProgram(self._id)
  File "/Users/dominiklang/Artemotion/venv/lib/python3.11/site-packages/OpenGL/error.py", line 230, in glCheckError
    raise self._errorClass(
OpenGL.error.GLError: GLError(
	err = 1282,
	description = b'invalid operation',
	baseOperation = glUseProgram,
	cArguments = (6,)
)
[2025-10-04 01:47:53.555] {                 Renderable.py: 183} (              UIMain3DSub:   ERROR) - Unable to use the GL program because:
Traceback (most recent call last):
  File "/Users/dominiklang/Artemotion/scripts/engine3d/core/GLProgram.py", line 131, in use
    pygl.glUseProgram(self._id)
  File "/Users/dominiklang/Artemotion/venv/lib/python3.11/site-packages/OpenGL/error.py", line 230, in glCheckError
    raise self._errorClass(
OpenGL.error.GLError: GLError(
	err = 1282,
	description = b'invalid operation',
	baseOperation = glUseProgram,
	cArguments = (6,)
)
[2025-10-04 01:47:53.559] {                 Renderable.py: 183} (              UIMain3DSub:   ERROR) - Unable to use the GL program because:
Traceback (most recent call last):
  File "/Users/dominiklang/Artemotion/scripts/engine3d/core/GLProgram.py", line 131, in use
    pygl.glUseProgram(self._id)
  File "/Users/dominiklang/Artemotion/venv/lib/python3.11/site-packages/OpenGL/error.py", line 230, in glCheckError
    raise self._errorClass(
OpenGL.error.GLError: GLError(
	err = 1282,
	description = b'invalid operation',
	baseOperation = glUseProgram,
	cArguments = (6,)
)
[2025-10-04 01:47:53.572] {                 Renderable.py: 183} (              UIMain3DSub:   ERROR) - Unable to use the GL program because:
Traceback (most recent call last):
  File "/Users/dominiklang/Artemotion/scripts/engine3d/core/GLProgram.py", line 131, in use
    pygl.glUseProgram(self._id)
  File "/Users/dominiklang/Artemotion/venv/lib/python3.11/site-packages/OpenGL/error.py", line 230, in glCheckError
    raise self._errorClass(
OpenGL.error.GLError: GLError(
	err = 1282,
	description = b'invalid operation',
	baseOperation = glUseProgram,
	cArguments = (6,)
)
[2025-10-04 01:47:53.576] {                 Renderable.py: 183} (              UIMain3DSub:   ERROR) - Unable to use the GL program because:
Traceback (most recent call last):
  File "/Users/dominiklang/Artemotion/scripts/engine3d/core/GLProgram.py", line 131, in use
    pygl.glUseProgram(self._id)
  File "/Users/dominiklang/Artemotion/venv/lib/python3.11/site-packages/OpenGL/error.py", line 230, in glCheckError
    raise self._errorClass(
OpenGL.error.GLError: GLError(
	err = 1282,
	description = b'invalid operation',
	baseOperation = glUseProgram,
	cArguments = (6,)
)
[2025-10-04 01:47:53.589] {                 Renderable.py: 183} (              UIMain3DSub:   ERROR) - Unable to use the GL program because:
Traceback (most recent call last):
  File "/Users/dominiklang/Artemotion/scripts/engine3d/core/GLProgram.py", line 131, in use
    pygl.glUseProgram(self._id)
  File "/Users/dominiklang/Artemotion/venv/lib/python3.11/site-packages/OpenGL/error.py", line 230, in glCheckError
    raise self._errorClass(
OpenGL.error.GLError: GLError(
	err = 1282,
	description = b'invalid operation',
	baseOperation = glUseProgram,
	cArguments = (6,)
)
[2025-10-04 01:47:53.596] {                 Renderable.py: 183} (              UIMain3DSub:   ERROR) - Unable to use the GL program because:
Traceback (most recent call last):
  File "/Users/dominiklang/Artemotion/scripts/engine3d/core/GLProgram.py", line 131, in use
    pygl.glUseProgram(self._id)
  File "/Users/dominiklang/Artemotion/venv/lib/python3.11/site-packages/OpenGL/error.py", line 230, in glCheckError
    raise self._errorClass(
OpenGL.error.GLError: GLError(
	err = 1282,
	description = b'invalid operation',
	baseOperation = glUseProgram,
	cArguments = (6,)
)
[2025-10-04 01:47:53.606] {                 Renderable.py: 183} (              UIMain3DSub:   ERROR) - Unable to use the GL program because:
Traceback (most recent call last):
  File "/Users/dominiklang/Artemotion/scripts/engine3d/core/GLProgram.py", line 131, in use
    pygl.glUseProgram(self._id)
  File "/Users/dominiklang/Artemotion/venv/lib/python3.11/site-packages/OpenGL/error.py", line 230, in glCheckError
    raise self._errorClass(
OpenGL.error.GLError: GLError(
	err = 1282,
	description = b'invalid operation',
	baseOperation = glUseProgram,
	cArguments = (6,)
)
[2025-10-04 01:47:53.618] {                 Renderable.py: 183} (              UIMain3DSub:   ERROR) - Unable to use the GL program because:
Traceback (most recent call last):
  File "/Users/dominiklang/Artemotion/scripts/engine3d/core/GLProgram.py", line 131, in use
    pygl.glUseProgram(self._id)
  File "/Users/dominiklang/Artemotion/venv/lib/python3.11/site-packages/OpenGL/error.py", line 230, in glCheckError
    raise self._errorClass(
OpenGL.error.GLError: GLError(
	err = 1282,
	description = b'invalid operation',
	baseOperation = glUseProgram,
	cArguments = (6,)
)
[2025-10-04 01:47:53.623] {                 Renderable.py: 183} (              UIMain3DSub:   ERROR) - Unable to use the GL program because:
Traceback (most recent call last):
  File "/Users/dominiklang/Artemotion/scripts/engine3d/core/GLProgram.py", line 131, in use
    pygl.glUseProgram(self._id)
  File "/Users/dominiklang/Artemotion/venv/lib/python3.11/site-packages/OpenGL/error.py", line 230, in glCheckError
    raise self._errorClass(
OpenGL.error.GLError: GLError(
	err = 1282,
	description = b'invalid operation',
	baseOperation = glUseProgram,
	cArguments = (6,)
)
[2025-10-04 01:47:53.639] {                 Renderable.py: 183} (              UIMain3DSub:   ERROR) - Unable to use the GL program because:
Traceback (most recent call last):
  File "/Users/dominiklang/Artemotion/scripts/engine3d/core/GLProgram.py", line 131, in use
    pygl.glUseProgram(self._id)
  File "/Users/dominiklang/Artemotion/venv/lib/python3.11/site-packages/OpenGL/error.py", line 230, in glCheckError
    raise self._errorClass(
OpenGL.error.GLError: GLError(
	err = 1282,
	description = b'invalid operation',
	baseOperation = glUseProgram,
	cArguments = (6,)
)
[2025-10-04 01:47:53.655] {                 Renderable.py: 183} (              UIMain3DSub:   ERROR) - Unable to use the GL program because:
Traceback (most recent call last):
  File "/Users/dominiklang/Artemotion/scripts/engine3d/core/GLProgram.py", line 131, in use
    pygl.glUseProgram(self._id)
  File "/Users/dominiklang/Artemotion/venv/lib/python3.11/site-packages/OpenGL/error.py", line 230, in glCheckError
    raise self._errorClass(
OpenGL.error.GLError: GLError(
	err = 1282,
	description = b'invalid operation',
	baseOperation = glUseProgram,
	cArguments = (6,)
)
[2025-10-04 01:47:53.681] {                 Renderable.py: 183} (              UIMain3DSub:   ERROR) - Unable to use the GL program because:
Traceback (most recent call last):
  File "/Users/dominiklang/Artemotion/scripts/engine3d/core/GLProgram.py", line 131, in use
    pygl.glUseProgram(self._id)
  File "/Users/dominiklang/Artemotion/venv/lib/python3.11/site-packages/OpenGL/error.py", line 230, in glCheckError
    raise self._errorClass(
OpenGL.error.GLError: GLError(
	err = 1282,
	description = b'invalid operation',
	baseOperation = glUseProgram,
	cArguments = (6,)
)
[2025-10-04 01:47:53.695] {                 Renderable.py: 183} (              UIMain3DSub:   ERROR) - Unable to use the GL program because:
Traceback (most recent call last):
  File "/Users/dominiklang/Artemotion/scripts/engine3d/core/GLProgram.py", line 131, in use
    pygl.glUseProgram(self._id)
  File "/Users/dominiklang/Artemotion/venv/lib/python3.11/site-packages/OpenGL/error.py", line 230, in glCheckError
    raise self._errorClass(
OpenGL.error.GLError: GLError(
	err = 1282,
	description = b'invalid operation',
	baseOperation = glUseProgram,
	cArguments = (6,)
)
[2025-10-04 01:47:53.705] {                 Renderable.py: 183} (              UIMain3DSub:   ERROR) - Unable to use the GL program because:
Traceback (most recent call last):
  File "/Users/dominiklang/Artemotion/scripts/engine3d/core/GLProgram.py", line 131, in use
    pygl.glUseProgram(self._id)
  File "/Users/dominiklang/Artemotion/venv/lib/python3.11/site-packages/OpenGL/error.py", line 230, in glCheckError
    raise self._errorClass(
OpenGL.error.GLError: GLError(
	err = 1282,
	description = b'invalid operation',
	baseOperation = glUseProgram,
	cArguments = (6,)
)
[2025-10-04 01:47:53.722] {                 Renderable.py: 183} (              UIMain3DSub:   ERROR) - Unable to use the GL program because:
Traceback (most recent call last):
  File "/Users/dominiklang/Artemotion/scripts/engine3d/core/GLProgram.py", line 131, in use
    pygl.glUseProgram(self._id)
  File "/Users/dominiklang/Artemotion/venv/lib/python3.11/site-packages/OpenGL/error.py", line 230, in glCheckError
    raise self._errorClass(
OpenGL.error.GLError: GLError(
	err = 1282,
	description = b'invalid operation',
	baseOperation = glUseProgram,
	cArguments = (6,)
)
[2025-10-04 01:47:53.745] {                 Renderable.py: 183} (              UIMain3DSub:   ERROR) - Unable to use the GL program because:
Traceback (most recent call last):
  File "/Users/dominiklang/Artemotion/scripts/engine3d/core/GLProgram.py", line 131, in use
    pygl.glUseProgram(self._id)
  File "/Users/dominiklang/Artemotion/venv/lib/python3.11/site-packages/OpenGL/error.py", line 230, in glCheckError
    raise self._errorClass(
OpenGL.error.GLError: GLError(
	err = 1282,
	description = b'invalid operation',
	baseOperation = glUseProgram,
	cArguments = (6,)
)
[2025-10-04 01:47:53.755] {                 Renderable.py: 183} (              UIMain3DSub:   ERROR) - Unable to use the GL program because:
Traceback (most recent call last):
  File "/Users/dominiklang/Artemotion/scripts/engine3d/core/GLProgram.py", line 131, in use
    pygl.glUseProgram(self._id)
  File "/Users/dominiklang/Artemotion/venv/lib/python3.11/site-packages/OpenGL/error.py", line 230, in glCheckError
    raise self._errorClass(
OpenGL.error.GLError: GLError(
	err = 1282,
	description = b'invalid operation',
	baseOperation = glUseProgram,
	cArguments = (6,)
)
[2025-10-04 01:47:53.772] {                 Renderable.py: 183} (              UIMain3DSub:   ERROR) - Unable to use the GL program because:
Traceback (most recent call last):
  File "/Users/dominiklang/Artemotion/scripts/engine3d/core/GLProgram.py", line 131, in use
    pygl.glUseProgram(self._id)
  File "/Users/dominiklang/Artemotion/venv/lib/python3.11/site-packages/OpenGL/error.py", line 230, in glCheckError
    raise self._errorClass(
OpenGL.error.GLError: GLError(
	err = 1282,
	description = b'invalid operation',
	baseOperation = glUseProgram,
	cArguments = (6,)
)
[2025-10-04 01:47:53.789] {                 Renderable.py: 183} (              UIMain3DSub:   ERROR) - Unable to use the GL program because:
Traceback (most recent call last):
  File "/Users/dominiklang/Artemotion/scripts/engine3d/core/GLProgram.py", line 131, in use
    pygl.glUseProgram(self._id)
  File "/Users/dominiklang/Artemotion/venv/lib/python3.11/site-packages/OpenGL/error.py", line 230, in glCheckError
    raise self._errorClass(
OpenGL.error.GLError: GLError(
	err = 1282,
	description = b'invalid operation',
	baseOperation = glUseProgram,
	cArguments = (6,)
)
[2025-10-04 01:47:53.793] {                 Renderable.py: 183} (              UIMain3DSub:   ERROR) - Unable to use the GL program because:
Traceback (most recent call last):
  File "/Users/dominiklang/Artemotion/scripts/engine3d/core/GLProgram.py", line 131, in use
    pygl.glUseProgram(self._id)
  File "/Users/dominiklang/Artemotion/venv/lib/python3.11/site-packages/OpenGL/error.py", line 230, in glCheckError
    raise self._errorClass(
OpenGL.error.GLError: GLError(
	err = 1282,
	description = b'invalid operation',
	baseOperation = glUseProgram,
	cArguments = (6,)
)
[2025-10-04 01:47:53.805] {                 Renderable.py: 183} (              UIMain3DSub:   ERROR) - Unable to use the GL program because:
Traceback (most recent call last):
  File "/Users/dominiklang/Artemotion/scripts/engine3d/core/GLProgram.py", line 131, in use
    pygl.glUseProgram(self._id)
  File "/Users/dominiklang/Artemotion/venv/lib/python3.11/site-packages/OpenGL/error.py", line 230, in glCheckError
    raise self._errorClass(
OpenGL.error.GLError: GLError(
	err = 1282,
	description = b'invalid operation',
	baseOperation = glUseProgram,
	cArguments = (6,)
)
[2025-10-04 01:47:53.813] {                 Renderable.py: 183} (              UIMain3DSub:   ERROR) - Unable to use the GL program because:
Traceback (most recent call last):
  File "/Users/dominiklang/Artemotion/scripts/engine3d/core/GLProgram.py", line 131, in use
    pygl.glUseProgram(self._id)
  File "/Users/dominiklang/Artemotion/venv/lib/python3.11/site-packages/OpenGL/error.py", line 230, in glCheckError
    raise self._errorClass(
OpenGL.error.GLError: GLError(
	err = 1282,
	description = b'invalid operation',
	baseOperation = glUseProgram,
	cArguments = (6,)
)
[2025-10-04 01:47:53.822] {                 Renderable.py: 183} (              UIMain3DSub:   ERROR) - Unable to use the GL program because:
Traceback (most recent call last):
  File "/Users/dominiklang/Artemotion/scripts/engine3d/core/GLProgram.py", line 131, in use
    pygl.glUseProgram(self._id)
  File "/Users/dominiklang/Artemotion/venv/lib/python3.11/site-packages/OpenGL/error.py", line 230, in glCheckError
    raise self._errorClass(
OpenGL.error.GLError: GLError(
	err = 1282,
	description = b'invalid operation',
	baseOperation = glUseProgram,
	cArguments = (6,)
)
[2025-10-04 01:47:53.827] {                 Renderable.py: 183} (              UIMain3DSub:   ERROR) - Unable to use the GL program because:
Traceback (most recent call last):
  File "/Users/dominiklang/Artemotion/scripts/engine3d/core/GLProgram.py", line 131, in use
    pygl.glUseProgram(self._id)
  File "/Users/dominiklang/Artemotion/venv/lib/python3.11/site-packages/OpenGL/error.py", line 230, in glCheckError
    raise self._errorClass(
OpenGL.error.GLError: GLError(
	err = 1282,
	description = b'invalid operation',
	baseOperation = glUseProgram,
	cArguments = (6,)
)
[2025-10-04 01:47:53.838] {                 Renderable.py: 183} (              UIMain3DSub:   ERROR) - Unable to use the GL program because:
Traceback (most recent call last):
  File "/Users/dominiklang/Artemotion/scripts/engine3d/core/GLProgram.py", line 131, in use
    pygl.glUseProgram(self._id)
  File "/Users/dominiklang/Artemotion/venv/lib/python3.11/site-packages/OpenGL/error.py", line 230, in glCheckError
    raise self._errorClass(
OpenGL.error.GLError: GLError(
	err = 1282,
	description = b'invalid operation',
	baseOperation = glUseProgram,
	cArguments = (6,)
)
[2025-10-04 01:47:53.854] {                 Renderable.py: 183} (              UIMain3DSub:   ERROR) - Unable to use the GL program because:
Traceback (most recent call last):
  File "/Users/dominiklang/Artemotion/scripts/engine3d/core/GLProgram.py", line 131, in use
    pygl.glUseProgram(self._id)
  File "/Users/dominiklang/Artemotion/venv/lib/python3.11/site-packages/OpenGL/error.py", line 230, in glCheckError
    raise self._errorClass(
OpenGL.error.GLError: GLError(
	err = 1282,
	description = b'invalid operation',
	baseOperation = glUseProgram,
	cArguments = (6,)
)
[2025-10-04 01:47:53.856] {                 Renderable.py: 183} (              UIMain3DSub:   ERROR) - Unable to use the GL program because:
Traceback (most recent call last):
  File "/Users/dominiklang/Artemotion/scripts/engine3d/core/GLProgram.py", line 131, in use
    pygl.glUseProgram(self._id)
  File "/Users/dominiklang/Artemotion/venv/lib/python3.11/site-packages/OpenGL/error.py", line 230, in glCheckError
    raise self._errorClass(
OpenGL.error.GLError: GLError(
	err = 1282,
	description = b'invalid operation',
	baseOperation = glUseProgram,
	cArguments = (6,)
)
[2025-10-04 01:47:53.859] {                 Renderable.py: 183} (              UIMain3DSub:   ERROR) - Unable to use the GL program because:
Traceback (most recent call last):
  File "/Users/dominiklang/Artemotion/scripts/engine3d/core/GLProgram.py", line 131, in use
    pygl.glUseProgram(self._id)
  File "/Users/dominiklang/Artemotion/venv/lib/python3.11/site-packages/OpenGL/error.py", line 230, in glCheckError
    raise self._errorClass(
OpenGL.error.GLError: GLError(
	err = 1282,
	description = b'invalid operation',
	baseOperation = glUseProgram,
	cArguments = (6,)
)
[2025-10-04 01:47:53.872] {                 Renderable.py: 183} (              UIMain3DSub:   ERROR) - Unable to use the GL program because:
Traceback (most recent call last):
  File "/Users/dominiklang/Artemotion/scripts/engine3d/core/GLProgram.py", line 131, in use
    pygl.glUseProgram(self._id)
  File "/Users/dominiklang/Artemotion/venv/lib/python3.11/site-packages/OpenGL/error.py", line 230, in glCheckError
    raise self._errorClass(
OpenGL.error.GLError: GLError(
	err = 1282,
	description = b'invalid operation',
	baseOperation = glUseProgram,
	cArguments = (6,)
)
[2025-10-04 01:47:53.876] {                 Renderable.py: 183} (              UIMain3DSub:   ERROR) - Unable to use the GL program because:
Traceback (most recent call last):
  File "/Users/dominiklang/Artemotion/scripts/engine3d/core/GLProgram.py", line 131, in use
    pygl.glUseProgram(self._id)
  File "/Users/dominiklang/Artemotion/venv/lib/python3.11/site-packages/OpenGL/error.py", line 230, in glCheckError
    raise self._errorClass(
OpenGL.error.GLError: GLError(
	err = 1282,
	description = b'invalid operation',
	baseOperation = glUseProgram,
	cArguments = (6,)
)
[2025-10-04 01:47:53.888] {                 Renderable.py: 183} (              UIMain3DSub:   ERROR) - Unable to use the GL program because:
Traceback (most recent call last):
  File "/Users/dominiklang/Artemotion/scripts/engine3d/core/GLProgram.py", line 131, in use
    pygl.glUseProgram(self._id)
  File "/Users/dominiklang/Artemotion/venv/lib/python3.11/site-packages/OpenGL/error.py", line 230, in glCheckError
    raise self._errorClass(
OpenGL.error.GLError: GLError(
	err = 1282,
	description = b'invalid operation',
	baseOperation = glUseProgram,
	cArguments = (6,)
)
[2025-10-04 01:47:53.905] {                 Renderable.py: 183} (              UIMain3DSub:   ERROR) - Unable to use the GL program because:
Traceback (most recent call last):
  File "/Users/dominiklang/Artemotion/scripts/engine3d/core/GLProgram.py", line 131, in use
    pygl.glUseProgram(self._id)
  File "/Users/dominiklang/Artemotion/venv/lib/python3.11/site-packages/OpenGL/error.py", line 230, in glCheckError
    raise self._errorClass(
OpenGL.error.GLError: GLError(
	err = 1282,
	description = b'invalid operation',
	baseOperation = glUseProgram,
	cArguments = (6,)
)
[2025-10-04 01:47:53.922] {                 Renderable.py: 183} (              UIMain3DSub:   ERROR) - Unable to use the GL program because:
Traceback (most recent call last):
  File "/Users/dominiklang/Artemotion/scripts/engine3d/core/GLProgram.py", line 131, in use
    pygl.glUseProgram(self._id)
  File "/Users/dominiklang/Artemotion/venv/lib/python3.11/site-packages/OpenGL/error.py", line 230, in glCheckError
    raise self._errorClass(
OpenGL.error.GLError: GLError(
	err = 1282,
	description = b'invalid operation',
	baseOperation = glUseProgram,
	cArguments = (6,)
)
[2025-10-04 01:47:53.938] {                 Renderable.py: 183} (              UIMain3DSub:   ERROR) - Unable to use the GL program because:
Traceback (most recent call last):
  File "/Users/dominiklang/Artemotion/scripts/engine3d/core/GLProgram.py", line 131, in use
    pygl.glUseProgram(self._id)
  File "/Users/dominiklang/Artemotion/venv/lib/python3.11/site-packages/OpenGL/error.py", line 230, in glCheckError
    raise self._errorClass(
OpenGL.error.GLError: GLError(
	err = 1282,
	description = b'invalid operation',
	baseOperation = glUseProgram,
	cArguments = (6,)
)
[2025-10-04 01:47:53.955] {                 Renderable.py: 183} (              UIMain3DSub:   ERROR) - Unable to use the GL program because:
Traceback (most recent call last):
  File "/Users/dominiklang/Artemotion/scripts/engine3d/core/GLProgram.py", line 131, in use
    pygl.glUseProgram(self._id)
  File "/Users/dominiklang/Artemotion/venv/lib/python3.11/site-packages/OpenGL/error.py", line 230, in glCheckError
    raise self._errorClass(
OpenGL.error.GLError: GLError(
	err = 1282,
	description = b'invalid operation',
	baseOperation = glUseProgram,
	cArguments = (6,)
)
[2025-10-04 01:47:53.972] {                 Renderable.py: 183} (              UIMain3DSub:   ERROR) - Unable to use the GL program because:
Traceback (most recent call last):
  File "/Users/dominiklang/Artemotion/scripts/engine3d/core/GLProgram.py", line 131, in use
    pygl.glUseProgram(self._id)
  File "/Users/dominiklang/Artemotion/venv/lib/python3.11/site-packages/OpenGL/error.py", line 230, in glCheckError
    raise self._errorClass(
OpenGL.error.GLError: GLError(
	err = 1282,
	description = b'invalid operation',
	baseOperation = glUseProgram,
	cArguments = (6,)
)
[2025-10-04 01:47:54.055] {                 Renderable.py: 183} (              UIMain3DSub:   ERROR) - Unable to use the GL program because:
Traceback (most recent call last):
  File "/Users/dominiklang/Artemotion/scripts/engine3d/core/GLProgram.py", line 131, in use
    pygl.glUseProgram(self._id)
  File "/Users/dominiklang/Artemotion/venv/lib/python3.11/site-packages/OpenGL/error.py", line 230, in glCheckError
    raise self._errorClass(
OpenGL.error.GLError: GLError(
	err = 1282,
	description = b'invalid operation',
	baseOperation = glUseProgram,
	cArguments = (6,)
)
